Workbook
Name sites: [1]Sheet3!$A:$B

Sheet Test
A1: Source | B1: Target
A2: https://serco.sharepoint.com/sites/SA-TECHM365DataMigration

Sheet Pilot-Wave1
A1: SITE NAME | B1: SITE URL (MAIN) | C1: Target URL | D1: Wave | E1: SITE TYPE | F1: SITE OWNERS - EMAIL | G1: SIZE IN GB | H1: BU | I1: Portfolio | J1: Active Site | K1: Action | L1: Site Exist in GCCH? | M1: Teams
A2: CCS_ASG_Team | B2: https://serco.sharepoint.com/sites/CCS_ASG_Team | D2: Wave 1 | E2: SharePoint | F2: Christina.Hall@serco-na.com | G2: 0 | H2: Corporate Services | I2: Technology | J2: Yes | K2: Migrate
A3: =_xlfn.XLOOKUP(B3,'All Sites_20260129180943356'!B:B,'All Sites_20260129180943356'!A:A) -> Cyber Opportunities | B3: https://serco.sharepoint.com/sites/CyberOpportunities | D3: Wave 1 | E3: MS Teams | F3: Tracy.West@serco-na.com | G3: 0 | H3: Corporate Services | I3: Technology | J3: Yes | K3: Migrate
A4: Agile Impact Leadership | B4: https://serco.sharepoint.com/sites/AgileImpactLeadership | D4: Wave 1 | E4: SharePoint | F4: Tracy.West@serco-na.com; Wayne.Borchers@serco-na.com; Timothy.Baker@serco-na.com | G4: 0 | H4: Corporate Services | I4: #N/A | J4: Yes | K4: Migrate
A5: =_xlfn.XLOOKUP(B5,'All Sites_20260129180943356'!B:B,'All Sites_20260129180943356'!A:A) -> Temp Site | B5: https://serco.sharepoint.com/sites/TempSite | D5: Wave 1 | E5: SharePoint | F5: Miles.Olson@serco-na.com | G5: 0.01 | H5: Corporate Services | I5: Technology | J5: Yes | K5: Migrate
A6: =_xlfn.XLOOKUP(B6,'All Sites_20260129180943356'!B:B,'All Sites_20260129180943356'!A:A) -> 30238.T13_N81F_OA Community Inventory Assessment | B6: https://serco.sharepoint.com/sites/30238.T13_N81F_OACommunityInventoryAssessment | D6: Wave 1 | E6: MS Teams | F6: Jason.Heuer@serco-na.com; Kelly.Cormican@serco-na.com | G6: 0.01 | H6: Corporate Services | I6: #N/A | J6: Yes | K6: Migrate
A7: =_xlfn.XLOOKUP(B7,'All Sites_20260129180943356'!B:B,'All Sites_20260129180943356'!A:A) -> AcqMgmt Group | B7: https://serco.sharepoint.com/sites/acqmgmt | D7: Wave 1 | E7: MS Teams | F7: Timothy.Baker@serco-na.com | G7: 0.01 | H7: Corporate Services | I7: Technology | J7: Yes | K7: Migrate
A8: =_xlfn.XLOOKUP(B8,'All Sites_20260129180943356'!B:B,'All Sites_20260129180943356'!A:A) -> Decision Support Laptop Reservation | B8: https://serco.sharepoint.com/sites/DecisionSupportLaptopReservation | D8: Wave 1 | E8: MS Teams | F8: Christopher.Pritchet@serco-na.com; Brock.Magnino@serco-na.com | G8: 0.01 | H8: Corporate Services | I8: #N/A | J8: Yes | K8: Migrate
A9: =_xlfn.XLOOKUP(B9,'All Sites_20260129180943356'!B:B,'All Sites_20260129180943356'!A:A) -> J-Plant Core | B9: https://serco.sharepoint.com/sites/J-PlantCore | D9: Wave 1 | E9: MS Teams | F9: Charles.Dewar@serco-na.com | G9: 0.01 | H9: Corporate Services | I9: Citizens Services | J9: Yes | K9: Migrate
A10: =_xlfn.XLOOKUP(B10,'All Sites_20260129180943356'!B:B,'All Sites_20260129180943356'!A:A) -> MTUAS | B10: https://serco.sharepoint.com/sites/MTUAS | D10: Wave 1 | E10: MS Teams | F10: Brian.Hall@serco-na.com | G10: 0.01 | H10: Corporate Services | I10: Technology | J10: Yes | K10: Migrate
A11: =_xlfn.XLOOKUP(B11,'All Sites_20260129180943356'!B:B,'All Sites_20260129180943356'!A:A) -> N81 Expeditionary Logistics | B11: https://serco.sharepoint.com/sites/N81ExpeditionaryLogistics | D11: Wave 1 | E11: MS Teams | F11: Jason.Heuer@serco-na.com | G11: 0.01 | H11: Corporate Services | I11: Technology | J11: Yes | K11: Migrate
A12: =_xlfn.XLOOKUP(B12,'All Sites_20260129180943356'!B:B,'All Sites_20260129180943356'!A:A) -> N81F_OA Community Inventory Assessment_30238.T13 | B12: https://serco.sharepoint.com/sites/N81F_OACommunityInventoryAssessment_30238.T13 | D12: Wave 1 | E12: MS Teams | F12: Jason.Heuer@serco-na.com; Kelly.Cormican@serco-na.com | G12: 0.01 | H12: Corporate Services | I12: #N/A | J12: Yes | K12: Migrate
A13: =_xlfn.XLOOKUP(B13,'All Sites_20260129180943356'!B:B,'All Sites_20260129180943356'!A:A) -> Sentinal | B13: https://serco.sharepoint.com/sites/Sentinal | D13: Wave 1 | E13: MS Teams | F13: Thomas.Glass@serco-na.com | G13: 0.01 | H13: Corporate Services | I13: Technology | J13: Yes | K13: Migrate | L13: https://gov.teams.microsoft.us/l/channel/19%3Agcch%3A55483ea836994cd18b870e0f2cf7b7b7%40thread.tacv2/22790%20Sentinel%20BCA?groupId=3c8c6446-af58-4ca2-aad4-2b966be48a77&tenantId=fb1f5cc5-be84-4881-b037-2d641aea97fd&ngc=true
A14: =_xlfn.XLOOKUP(B14,'All Sites_20260129180943356'!B:B,'All Sites_20260129180943356'!A:A) -> Serco Human Capital | B14: https://serco.sharepoint.com/sites/SercoHumanCapital | D14: Wave 1 | E14: MS Teams | F14: Timothy.Winand@serco-na.com | G14: 0.01 | H14: Corporate Services | I14: Technology | J14: Yes | K14: Migrate
A15: =_xlfn.XLOOKUP(B15,'All Sites_20260129180943356'!B:B,'All Sites_20260129180943356'!A:A) -> Serco Human Capital Community of Interest | B15: https://serco.sharepoint.com/sites/SercoHumanCapitalCommunityofInterest | D15: Wave 1 | E15: MS Teams | F15: Timothy.Winand@serco-na.com | G15: 0.01 | H15: Corporate Services | I15: Technology | J15: Yes | K15: Migrate
A16: =_xlfn.XLOOKUP(B16,'All Sites_20260129180943356'!B:B,'All Sites_20260129180943356'!A:A) -> Serco Human Capital Consulting | B16: https://serco.sharepoint.com/sites/SercoHumanCapitalConsulting | D16: Wave 1 | E16: MS Teams | F16: Timothy.Winand@serco-na.com | G16: 0.01 | H16: Corporate Services | I16: Technology | J16: Yes | K16: Migrate
A17: =_xlfn.XLOOKUP(B17,'All Sites_20260129180943356'!B:B,'All Sites_20260129180943356'!A:A) -> AFRL RW RFP | B17: https://serco.sharepoint.com/sites/AFRLRWRFP | D17: Wave 1 | E17: MS Teams | F17: Cheryl.Lawrence@serco-na.com; Matthew.Imperial@serco-na.com | G17: 0.01 | H17: Corporate Services | I17: #N/A | J17: Yes | K17: Migrate | L17: Yes | M17: https://teams.cloud.microsoft/l/team/19%3AE-ra82ye9-n1kAiAnOa5OJN6szX3IK-PUvdYBK3c5iE1%40thread.tacv2/conversations?groupId=25f52227-6b74-4d0a-a600-9be8da78c1dc&tenantId=f93616dd-45a6-40c8-9e29-adab2fb5f25c
A18: =_xlfn.XLOOKUP(B18,'All Sites_20260129180943356'!B:B,'All Sites_20260129180943356'!A:A) -> Airbus Training Helicopter Study | B18: https://serco.sharepoint.com/sites/AirbusTrainingHelicopterStudy | D18: Wave 1 | E18: MS Teams | F18: Brian.Stehle@serco-na.com; Timothy.Hope@serco-na.com | G18: 0.01 | H18: Corporate Services | I18: #N/A | J18: Yes | K18: Migrate
A19: =_xlfn.XLOOKUP(B19,'All Sites_20260129180943356'!B:B,'All Sites_20260129180943356'!A:A) -> BAE Development and Support | B19: https://serco.sharepoint.com/sites/BAEDevelopmentandSupport | D19: Wave 1 | E19: MS Teams | F19: Charles.Dewar@serco-na.com | G19: 0.01 | H19: Corporate Services | I19: Citizens Services | J19: Yes | K19: Migrate
A20: =_xlfn.XLOOKUP(B20,'All Sites_20260129180943356'!B:B,'All Sites_20260129180943356'!A:A) -> Bell Flight Special Mission Aircraft Market Assessment | B20: https://serco.sharepoint.com/sites/BellFlightSpecialMissionAircraftMarketAssessment | D20: Wave 1 | E20: MS Teams | F20: Timothy.Hope@serco-na.com | G20: 0.01 | H20: Corporate Services | I20: Technology | J20: Yes | K20: Migrate
A21: =_xlfn.XLOOKUP(B21,'All Sites_20260129180943356'!B:B,'All Sites_20260129180943356'!A:A) -> Bendix Road Office | B21: https://serco.sharepoint.com/sites/BendixRoadOffice | D21: Wave 1 | E21: MS Teams | F21: Matthew.Sharpe@serco-na.com | G21: 0.01 | H21: Corporate Services | I21: Technology | J21: Yes | K21: Migrate
A22: =_xlfn.XLOOKUP(B22,'All Sites_20260129180943356'!B:B,'All Sites_20260129180943356'!A:A) -> Brazilian Antartic Support Ship - NApAnt | B22: https://serco.sharepoint.com/sites/BrazilianAntarticSupportShip-NApAnt | D22: Wave 1 | E22: MS Teams | F22: Daniel.Mattioda@serco-na.com; John.Boehmer@serco-na.com | G22: 0.01 | H22: Corporate Services | I22: #N/A | J22: Yes | K22: Migrate
A23: =_xlfn.XLOOKUP(B23,'All Sites_20260129180943356'!B:B,'All Sites_20260129180943356'!A:A) -> CLS Planning | B23: https://serco.sharepoint.com/sites/CLSPlanning | D23: Wave 1 | E23: MS Teams | F23: Michael.Lee@serco-na.com; Melinda.Grigorian@serco-na.com; Jonathan.Downing@serco-na.com | G23: 0.01 | H23: Corporate Services | I23: #N/A | J23: Yes | K23: Migrate
A24: =_xlfn.XLOOKUP(B24,'All Sites_20260129180943356'!B:B,'All Sites_20260129180943356'!A:A) -> DON HCS OARS | B24: https://serco.sharepoint.com/sites/DONHCSOARS | D24: Wave 1 | E24: MS Teams | F24: Albert.Moseley@serco-na.com | G24: 0.01 | H24: Corporate Services | I24: Technology | J24: Yes | K24: Migrate
A25: =_xlfn.XLOOKUP(B25,'All Sites_20260129180943356'!B:B,'All Sites_20260129180943356'!A:A) -> F35 AVMS Avionics Branch Organizational Assessment | B25: https://serco.sharepoint.com/sites/F35AVMSAvionicsOrganizationalStudy | D25: Wave 1 | E25: MS Teams | F25: Albert.Moseley@serco-na.com | G25: 0.01 | H25: Corporate Services | I25: Technology | J25: Yes | K25: Migrate
A26: =_xlfn.XLOOKUP(B26,'All Sites_20260129180943356'!B:B,'All Sites_20260129180943356'!A:A) -> FFGX-Automation | B26: https://serco.sharepoint.com/sites/FFGX-Automation | D26: Wave 1 | E26: MS Teams | F26: Miles.Olson@serco-na.com; Kyle.Hagen@serco-na.com; Kelly.Cormican@serco-na.com | G26: 0.01 | H26: Corporate Services | I26: #N/A | J26: Yes | K26: Migrate
A27: =_xlfn.XLOOKUP(B27,'All Sites_20260129180943356'!B:B,'All Sites_20260129180943356'!A:A) -> HWW Shared Content | B27: https://serco.sharepoint.com/sites/HWWSharedContent246 | D27: Wave 1 | E27: MS Teams | F27: Timothy.Hope@serco-na.com | G27: 0.01 | H27: Corporate Services | I27: Technology | J27: Yes | K27: Migrate
A28: =_xlfn.XLOOKUP(B28,'All Sites_20260129180943356'!B:B,'All Sites_20260129180943356'!A:A) -> LRSO | B28: https://serco.sharepoint.com/sites/LRSO738 | D28: Wave 1 | E28: MS Teams | F28: Melinda.Grigorian@serco-na.com; Thomas.Glass@serco-na.com | G28: 0.01 | H28: Corporate Services | I28: #N/A | J28: Yes | K28: Migrate | L28: 32008 LRSO PS-BCA | MG-AF/SF Market Projects #2 | Microsoft Teams
A29: =_xlfn.XLOOKUP(B29,'All Sites_20260129180943356'!B:B,'All Sites_20260129180943356'!A:A) -> LSV SOW - (using Vessel Construction Management) | B29: https://serco.sharepoint.com/sites/LSVSOW-usingVesselConstructionManagement | D29: Wave 1 | E29: MS Teams | F29: Brian.Stehle@serco-na.com | G29: 0.01 | H29: Corporate Services | I29: Technology | J29: Yes | K29: Migrate
A30: =_xlfn.XLOOKUP(B30,'All Sites_20260129180943356'!B:B,'All Sites_20260129180943356'!A:A) -> PNT PO (JSSMO) Production Analyses | B30: https://serco.sharepoint.com/sites/PNTPOJSSMOProductionAnalyses | D30: Wave 1 | E30: MS Teams | F30: Christopher.Pritchet@serco-na.com | G30: 0.01 | H30: Corporate Services | I30: Technology | J30: Yes | K30: Migrate
A31: =_xlfn.XLOOKUP(B31,'All Sites_20260129180943356'!B:B,'All Sites_20260129180943356'!A:A) -> SE&V CBA (Unclass) | B31: https://serco.sharepoint.com/sites/SEVCBAUnclass | D31: Wave 1 | E31: MS Teams | F31: Christopher.Pritchet@serco-na.com | G31: 0.01 | H31: Corporate Services | I31: Technology | J31: Yes | K31: Migrate
A32: =_xlfn.XLOOKUP(B32,'All Sites_20260129180943356'!B:B,'All Sites_20260129180943356'!A:A) -> SOCOM MAECE | B32: https://serco.sharepoint.com/sites/SOCOMMAECE | D32: Wave 1 | E32: MS Teams | F32: Christopher.Pritchet@serco-na.com; William.Burnette@serco-na.com; Vincent.Amato@serco-na.com | G32: 0.01 | H32: Corporate Services | I32: #N/A | J32: Yes | K32: Migrate
A33: =_xlfn.XLOOKUP(B33,'All Sites_20260129180943356'!B:B,'All Sites_20260129180943356'!A:A) -> SOCOM PEO RW | B33: https://serco.sharepoint.com/sites/SOCOMPEORW | D33: Wave 1 | E33: MS Teams | F33: Brian.Stehle@serco-na.com | G33: 0.01 | H33: Corporate Services | I33: Technology | J33: Yes | K33: Migrate
A34: =_xlfn.XLOOKUP(B34,'All Sites_20260129180943356'!B:B,'All Sites_20260129180943356'!A:A) -> Training Initiatives | B34: https://serco.sharepoint.com/sites/TrainingInitiatives | D34: Wave 1 | E34: MS Teams | F34: Timothy.Hope@serco-na.com | G34: 0.01 | H34: Corporate Services | I34: Technology | J34: Yes | K34: Migrate
A35: =_xlfn.XLOOKUP(B35,'All Sites_20260129180943356'!B:B,'All Sites_20260129180943356'!A:A) -> AmeriCorps OARS Team | B35: https://serco.sharepoint.com/sites/americorpsoarsteam | D35: Wave 1 | E35: MS Teams | F35: Kelly.Cormican@serco-na.com | G35: 0.02 | H35: Corporate Services | I35: Technology | J35: Yes | K35: Migrate
A36: =_xlfn.XLOOKUP(B36,'All Sites_20260129180943356'!B:B,'All Sites_20260129180943356'!A:A) -> PRO | B36: https://serco.sharepoint.com/sites/pro | D36: Wave 1 | E36: MS Teams | F36: Timothy.Baker@serco-na.com | G36: 0.02 | H36: Corporate Services | I36: Technology | J36: Yes | K36: Migrate
A37: =_xlfn.XLOOKUP(B37,'All Sites_20260129180943356'!B:B,'All Sites_20260129180943356'!A:A) -> F-35 LCSP Development | B37: https://serco.sharepoint.com/sites/F-35LCSPDevelopment | D37: Wave 1 | E37: MS Teams | F37: Wayne.Borchers@serco-na.com | G37: 0.02 | H37: Corporate Services | I37: Technology | J37: Yes | K37: Migrate
A38: =_xlfn.XLOOKUP(B38,'All Sites_20260129180943356'!B:B,'All Sites_20260129180943356'!A:A) -> LRSO ILA | B38: https://serco.sharepoint.com/sites/LRSO | D38: Wave 1 | E38: MS Teams | F38: Whitney.Sessoms@SERCO-NA.COM | G38: 0.02 | H38: Corporate Services | I38: Technology | J38: Yes | K38: Migrate
A39: =_xlfn.XLOOKUP(B39,'All Sites_20260129180943356'!B:B,'All Sites_20260129180943356'!A:A) -> SAMI C5ISR Enterprise Architecture | B39: https://serco.sharepoint.com/sites/SAMIC5ISREnterpriseArchitecture | D39: Wave 1 | E39: MS Teams | F39: Tracy.West@serco-na.com; Albert.Moseley@serco-na.com; Wayne.Borchers@serco-na.com | G39: 0.02 | H39: Corporate Services | I39: #N/A | J39: Yes | K39: Migrate
A40: =_xlfn.XLOOKUP(B40,'All Sites_20260129180943356'!B:B,'All Sites_20260129180943356'!A:A) -> EFR CDD | B40: https://serco.sharepoint.com/sites/EFRCDD | D40: Wave 1 | E40: MS Teams | F40: Vincent.Amato@serco-na.com | G40: 0.03 | H40: Corporate Services | I40: Technology | J40: Yes | K40: Migrate
...

Sheet Wave1B
A1: SITE Name | B1: SITE URL (MAIN) | C1: SIZE IN GB | D1: SITE OWNERS - EMAIL | E1: BU | F1: Portfolio | G1: Wave | H1: Action | I1: IN PILOT | J1: Site Exist in GCCH? | K1: Teams
A2: AAAA | B2: https://serco.sharepoint.com/sites/aaaa | D2: Michael.J.Harris@serco-na.com | E2: Corporate Services | F2: Technology | G2: Wave 1 | H2: Migrate | I2: =_xlfn.XLOOKUP(B2,'Pilot-Wave1'!B:B,'Pilot-Wave1'!D:D) -> #N/A
A3: AAAAPlanning | B3: https://serco.sharepoint.com/sites/aaaaplanning | D3: Michael.J.Harris@serco-na.com | E3: Corporate Services | F3: Technology | G3: Wave 1 | H3: Migrate | I3: =_xlfn.XLOOKUP(B3,'Pilot-Wave1'!B:B,'Pilot-Wave1'!D:D) -> #N/A
A4: Acquisition Management (AQM) | B4: https://serco.sharepoint.com/sites/AFSFMarketTeam | D4: Raymond.Wier@serco-na.com | E4: Corporate Services | F4: Technology | G4: Wave 1 | H4: Migrate | I4: =_xlfn.XLOOKUP(B4,'Pilot-Wave1'!B:B,'Pilot-Wave1'!D:D) -> #N/A | J4: https://gov.teams.microsoft.us/l/team/19%3Agcch%3Af9f705e178ae4d588e8f42e0406241f8%40thread.tacv2/conversations?groupId=d95aa34f-d2f3-4d7e-a0ab-ed6d7d8c8d22&tenantId=fb1f5cc5-be84-4881-b037-2d641aea97fd
A5: WRO Team | B5: https://serco.sharepoint.com/sites/AFWROSpecialProjects | D5: Raymond.Wier@serco-na.com | E5: Corporate Services | F5: Technology | G5: Wave 1 | H5: Migrate | I5: =_xlfn.XLOOKUP(B5,'Pilot-Wave1'!B:B,'Pilot-Wave1'!D:D) -> #N/A
A6: AHFRM | B6: https://serco.sharepoint.com/sites/ahfrm | D6: Raymond.Wier@serco-na.com | E6: Corporate Services | F6: Technology | G6: Wave 1 | H6: Migrate | I6: =_xlfn.XLOOKUP(B6,'Pilot-Wave1'!B:B,'Pilot-Wave1'!D:D) -> #N/A
A7: AHFRM Rapid Fielding Planning and Support-AHFRM DTIC Management Channel | B7: https://serco.sharepoint.com/sites/AHFRMDTICKICKOFF-AHFRMDTICManagementChannel | D7: Steven.Yelverton@serco-na.com | E7: Corporate Services | F7: Technology | G7: Wave 1 | H7: Migrate | I7: =_xlfn.XLOOKUP(B7,'Pilot-Wave1'!B:B,'Pilot-Wave1'!D:D) -> #N/A
A8: AHFRM Manufacturing Emails | B8: https://serco.sharepoint.com/sites/AHFRMManufacturingEmails | D8: Brian.Townsend@serco-na.com | E8: Corporate Services | F8: Technology | G8: Wave 1 | H8: Migrate | I8: =_xlfn.XLOOKUP(B8,'Pilot-Wave1'!B:B,'Pilot-Wave1'!D:D) -> #N/A
A9: AmeriCorps Workforce Analysis | B9: https://serco.sharepoint.com/sites/AmeriCorpsWorkforceAnalysis | D9: Allison.Gervasio@serco-na.com | E9: Corporate Services | F9: Technology | G9: Wave 1 | H9: Migrate | I9: =_xlfn.XLOOKUP(B9,'Pilot-Wave1'!B:B,'Pilot-Wave1'!D:D) -> #N/A
A10: Angelo B-52 Files | B10: https://serco.sharepoint.com/sites/AngeloFiles | D10: Brian.Townsend@serco-na.com | E10: Corporate Services | F10: Technology | G10: Wave 1 | H10: Migrate | I10: =_xlfn.XLOOKUP(B10,'Pilot-Wave1'!B:B,'Pilot-Wave1'!D:D) -> #N/A
A11: Armed Overwatch | B11: https://serco.sharepoint.com/sites/ArmedOverwatch | D11: Gary.Leavy@serco-na.com | E11: Corporate Services | F11: Technology | G11: Wave 1 | H11: Migrate | I11: =_xlfn.XLOOKUP(B11,'Pilot-Wave1'!B:B,'Pilot-Wave1'!D:D) -> #N/A
A12: Army CONOPS Team | B12: https://serco.sharepoint.com/sites/ArmyCONOPSTeam | D12: Jay.Voorhees@serco-na.com | E12: Corporate Services | F12: Technology | G12: Wave 1 | H12: Migrate | I12: =_xlfn.XLOOKUP(B12,'Pilot-Wave1'!B:B,'Pilot-Wave1'!D:D) -> #N/A
A13: Army Team | B13: https://serco.sharepoint.com/sites/armyteam | D13: Michael.J.Harris@serco-na.com | E13: Corporate Services | F13: Technology | G13: Wave 1 | H13: Migrate | I13: =_xlfn.XLOOKUP(B13,'Pilot-Wave1'!B:B,'Pilot-Wave1'!D:D) -> #N/A
A14: AUSA Group | B14: https://serco.sharepoint.com/sites/AUSAGroup | D14: Michael.J.Harris@serco-na.com | E14: Corporate Services | F14: Technology | G14: Wave 1 | H14: Migrate | I14: =_xlfn.XLOOKUP(B14,'Pilot-Wave1'!B:B,'Pilot-Wave1'!D:D) -> #N/A
A15: B-52 DTIC IAC Team | B15: https://serco.sharepoint.com/sites/B-52DTICIACTeam | D15: Brian.Townsend@serco-na.com | E15: Corporate Services | F15: Technology | G15: Wave 1 | H15: Migrate | I15: =_xlfn.XLOOKUP(B15,'Pilot-Wave1'!B:B,'Pilot-Wave1'!D:D) -> #N/A | J15: https://gov.teams.microsoft.us/l/channel/19%3Agcch%3Ad84581d74cd642a2a5d7289286422301%40thread.tacv2/31688%20B-52%20Analysis%20and%20Modernization?groupId=d63110a1-af9a-4b18-a770-bf272eaafe3b&tenantId=fb1f5cc5-be84-4881-b037-2d641aea97fd&ngc=true
A16: B-52 Legacy TS PWS | B16: https://serco.sharepoint.com/sites/B-52LegacyTSPWS | D16: Brian.Townsend@serco-na.com | E16: Corporate Services | F16: Technology | G16: Wave 1 | H16: Migrate | I16: =_xlfn.XLOOKUP(B16,'Pilot-Wave1'!B:B,'Pilot-Wave1'!D:D) -> #N/A
A17: B-52 Nuc Cert Collaboration | B17: https://serco.sharepoint.com/sites/B-52NucCertCollaboration | D17: Brian.Townsend@serco-na.com | E17: Corporate Services | F17: Technology | G17: Wave 1 | H17: Migrate | I17: =_xlfn.XLOOKUP(B17,'Pilot-Wave1'!B:B,'Pilot-Wave1'!D:D) -> #N/A | J17: https://gov.teams.microsoft.us/l/team/19%3Agcch%3Ac923882e1fae430db5a2a5b92ae4857e%40thread.tacv2/conversations?groupId=6558baf4-9ed8-4d91-95bf-6e8e7a9df34b&tenantId=fb1f5cc5-be84-4881-b037-2d641aea97fd
A18: B-52 TS | B18: https://serco.sharepoint.com/sites/B-52TS | D18: Gary.Leavy@serco-na.com | E18: Corporate Services | F18: Technology | G18: Wave 1 | H18: Migrate | I18: =_xlfn.XLOOKUP(B18,'Pilot-Wave1'!B:B,'Pilot-Wave1'!D:D) -> #N/A
A19: CBP RFI | B19: https://serco.sharepoint.com/sites/CBPRFI | D19: Maggie.Irons@serco-na.com | E19: Corporate Services | F19: Technology | G19: Wave 1 | H19: Migrate | I19: =_xlfn.XLOOKUP(B19,'Pilot-Wave1'!B:B,'Pilot-Wave1'!D:D) -> #N/A
A20: DAF RCO 24-C-0007 | B20: https://serco.sharepoint.com/sites/DAFRCO24-C-0007 | D20: Alexander.Brown@serco-na.com | E20: Corporate Services | F20: Technology | G20: Wave 1 | H20: Migrate | I20: =_xlfn.XLOOKUP(B20,'Pilot-Wave1'!B:B,'Pilot-Wave1'!D:D) -> Wave 1
A21: DAF RCO Bridge | B21: https://serco.sharepoint.com/sites/DAFRCOBridge | D21: Alexander.Brown@serco-na.com | E21: Corporate Services | F21: Technology | G21: Wave 1 | H21: Migrate | I21: =_xlfn.XLOOKUP(B21,'Pilot-Wave1'!B:B,'Pilot-Wave1'!D:D) -> #N/A
A22: Defense Exportability Features - Bell | B22: https://serco.sharepoint.com/sites/DefenseExportabilityFeatures-Bell | D22: Joana.Rivera@serco-na.com | E22: Corporate Services | F22: Technology | G22: Wave 1 | H22: Migrate | I22: =_xlfn.XLOOKUP(B22,'Pilot-Wave1'!B:B,'Pilot-Wave1'!D:D) -> #N/A
A23: DHS FPS Acquisition #32094 | B23: https://serco.sharepoint.com/sites/DHSFPSAcquisition32094 | D23: Leonard.Geshan@serco-na.com | E23: Corporate Services | F23: Technology | G23: Wave 1 | H23: Migrate | I23: =_xlfn.XLOOKUP(B23,'Pilot-Wave1'!B:B,'Pilot-Wave1'!D:D) -> #N/A
A24: Digital Enterprise BD Campaign-DE Consortium 2025 | B24: https://serco.sharepoint.com/sites/DigitalEnterprise-EWAACDEConsortium | D24: Robert.Hoffman@serco-na.com | E24: Corporate Services | F24: Technology | G24: Wave 1 | H24: Migrate | I24: =_xlfn.XLOOKUP(B24,'Pilot-Wave1'!B:B,'Pilot-Wave1'!D:D) -> #N/A
A25: DTIC IAC MAC - Pool One | B25: https://serco.sharepoint.com/sites/DTICIACMAC-PoolOne | D25: Raymond.Wier@serco-na.com | E25: Corporate Services | F25: Technology | G25: Wave 1 | H25: Migrate | I25: =_xlfn.XLOOKUP(B25,'Pilot-Wave1'!B:B,'Pilot-Wave1'!D:D) -> #N/A
A26: DTIC TO # 1 Group | B26: https://serco.sharepoint.com/sites/DTICTO1Group | D26: Robert.Hoffman@serco-na.com | E26: Corporate Services | F26: Technology | G26: Wave 1 | H26: Migrate | I26: =_xlfn.XLOOKUP(B26,'Pilot-Wave1'!B:B,'Pilot-Wave1'!D:D) -> #N/A
A27: Eglin Wide Agile Acquisition Contract (EWAAC) | B27: https://serco.sharepoint.com/sites/EglinWideAgileAcquisitionContractEWAAC | D27: Robert.Hoffman@serco-na.com | E27: Corporate Services | F27: Technology | G27: Wave 1 | H27: Migrate | I27: =_xlfn.XLOOKUP(B27,'Pilot-Wave1'!B:B,'Pilot-Wave1'!D:D) -> #N/A
A28: F-35 FM KBS | B28: https://serco.sharepoint.com/sites/F-35FMKBS | D28: Alex.Stathopoulos@serco-na.com | E28: Corporate Services | F28: Technology | G28: Wave 1 | H28: Migrate | I28: =_xlfn.XLOOKUP(B28,'Pilot-Wave1'!B:B,'Pilot-Wave1'!D:D) -> #N/A
A29: F-35 Logistics KBS | B29: https://serco.sharepoint.com/sites/F-35LogisticsKBS | D29: Alex.Stathopoulos@serco-na.com | E29: Corporate Services | F29: Technology | G29: Wave 1 | H29: Migrate | I29: =_xlfn.XLOOKUP(B29,'Pilot-Wave1'!B:B,'Pilot-Wave1'!D:D) -> #N/A
... A35: JSSMO (PNT PO) - Wright Patterson Client Site Team | B35: https://serco.sharepoint.com/sites/JSSMOPNTPO-WrightPattersonClientSiteTeam | D35: Jeffrey.Braun@serco-na.com | E35: Corporate Services | F35: Technology | G35: Wave 1 | H35: Migrate | I35: =_xlfn.XLOOKUP(B35,'Pilot-Wave1'!B:B,'Pilot-Wave1'!D:D) -> #N/A
A36: KC-135 AW | B36: https://serco.sharepoint.com/sites/KC-135AW | D36: Brian.Townsend@serco-na.com | E36: Corporate Services | F36: Technology | G36: Wave 1 | H36: Migrate | I36: =_xlfn.XLOOKUP(B36,'Pilot-Wave1'!B:B,'Pilot-Wave1'!D:D) -> #N/A | J36: https://gov.teams.microsoft.us/l/team/19%3Agcch%3A5b0526e975a748debd9231e2ddab8b70%40thread.tacv2/conversations?groupId=59010a5f-cd41-429a-9cf5-006a8ffdf72a&tenantId=fb1f5cc5-be84-4881-b037-2d641aea97fd
A37: KC-135 Engineering Support | B37: https://serco.sharepoint.com/sites/KC-135EngineeringSupport | D37: Brian.Townsend@serco-na.com | E37: Corporate Services | F37: Technology | G37: Wave 1 | H37: Migrate | I37: =_xlfn.XLOOKUP(B37,'Pilot-Wave1'!B:B,'Pilot-Wave1'!D:D) -> #N/A | J37: https://gov.teams.microsoft.us/l/team/19%3Agcch%3A5b0526e975a748debd9231e2ddab8b70%40thread.tacv2/conversations?groupId=59010a5f-cd41-429a-9cf5-006a8ffdf72a&tenantId=fb1f5cc5-be84-4881-b037-2d641aea97fd
A38: MDA Threat Systems Engineering -Threat Products and Services | B38: https://serco.sharepoint.com/sites/MDAThreatSystemsEngineering-ThreatProductsandServices | D38: Robert.Hoffman@serco-na.com | E38: Corporate Services | F38: Technology | G38: Wave 1 | H38: Migrate | I38: =_xlfn.XLOOKUP(B38,'Pilot-Wave1'!B:B,'Pilot-Wave1'!D:D) -> #N/A
A39: N81F Combat System Sustainment | B39: https://serco.sharepoint.com/sites/N81FCombatSystemSustainment | D39: Allison.Gervasio@serco-na.com | E39: Corporate Services | F39: Technology | G39: Wave 1 | H39: Migrate | I39: =_xlfn.XLOOKUP(B39,'Pilot-Wave1'!B:B,'Pilot-Wave1'!D:D) -> #N/A
A40: Navigating Business Webinar Series | B40: https://serco.sharepoint.com/sites/NavigatingBusinessWebinarSeries | D40: Allison.Gervasio@serco-na.com | E40: Corporate Services | F40: Technology | G40: Wave 1 | H40: Migrate | I40: =_xlfn.XLOOKUP(B40,'Pilot-Wave1'!B:B,'Pilot-Wave1'!D:D) -> #N/A
A41: NIH NIAID | B41: https://serco.sharepoint.com/sites/NIHNIAID | D41: Allison.Gervasio@serco-na.com | E41: Corporate Services | F41: Technology | G41: Wave 1 | H41: Migrate | I41: =_xlfn.XLOOKUP(B41,'Pilot-Wave1'!B:B,'Pilot-Wave1'!D:D) -> #N/A
A42: PNT - Independent Review Team | B42: https://serco.sharepoint.com/sites/PNT-IndependentReviewTeam | D42: Till.Schanz@serco-na.com | E42: Corporate Services | F42: Technology | G42: Wave 1 | H42: Migrate | I42: =_xlfn.XLOOKUP(B42,'Pilot-Wave1'!B:B,'Pilot-Wave1'!D:D) -> #N/A
A43: AF PNT (JSSMO) Leads | B43: https://serco.sharepoint.com/sites/PNTJSSMOLeads | D43: Till.Schanz@serco-na.com | E43: Corporate Services | F43: Technology | G43: Wave 1 | H43: Migrate | I43: =_xlfn.XLOOKUP(B43,'Pilot-Wave1'!B:B,'Pilot-Wave1'!D:D) -> #N/A
A44: PNT PO Strategic Planning | B44: https://serco.sharepoint.com/sites/PNTPOStrategicPlanning | D44: Till.Schanz@serco-na.com | E44: Corporate Services | F44: Technology | G44: Wave 1 | H44: Migrate | I44: =_xlfn.XLOOKUP(B44,'Pilot-Wave1'!B:B,'Pilot-Wave1'!D:D) -> #N/A
A45: PNT Proposal 2025 | B45: https://serco.sharepoint.com/sites/PNTProposal2025 | D45: Till.Schanz@serco-na.com | E45: Corporate Services | F45: Technology | G45: Wave 1 | H45: Migrate | I45: =_xlfn.XLOOKUP(B45,'Pilot-Wave1'!B:B,'Pilot-Wave1'!D:D) -> #N/A
...

Sheet Wave1C
A1: MIGRATE | B1: SiteUrl | C1: WORKSTREAM | D1: Source | E1: UserDisplay | F1: UserEmail | G1: IDENTITY TYPE | H1: BU | I1: Program | J1: WAVE-1 | K1: OWNERS-EMAIL | L1: OWNERS-DISPLAYNAME | M1: Notes
A2: W1 | B2: https://serco.sharepoint.com/sites/GEODSSSPACEFENCE-QCLS | C2: TEAMS | D2: Owner | E2: Akins, Jessica, K (Serco NA US) | F2: Jessica.Akins@serco-na.com | G2: User | H2: SI2 | I2: C4ISR SS | J2: WAVE-1 | K2: Jessica.Akins@serco-na.com | L2: Akins, Jessica, K (Serco NA US)
A3: W1 | B3: https://serco.sharepoint.com/sites/IMCOMDeploymentOnBoarding | C3: TEAMS | D3: Owner | E3: Akins, Jessica, K (Serco NA US) | F3: Jessica.Akins@serco-na.com | G3: User | H3: SI2 | I3: C4ISR SS | J3: WAVE-1 | K3: Jessica.Akins@serco-na.com | L3: Akins, Jessica, K (Serco NA US)
A4: W1 | B4: https://serco.sharepoint.com/sites/PensacolaPlanner | C4: SPO - M365 GROUP | D4: Owner | E4: Allen, David, E (Serco NA US) | F4: David.Allen@SERCO-NA.COM | G4: User | H4: SI2 | I4: C4ISR SS | J4: WAVE-1 | K4: David.Allen@SERCO-NA.COM | L4: Allen, David, E (Serco NA US)
A5: W1 | B5: https://serco.sharepoint.com/sites/ResourcePlanning617 | C5: SPO - M365 GROUP | D5: Owner | E5: Allen, David, E (Serco NA US) | F5: David.Allen@SERCO-NA.COM | G5: User | H5: SI2 | I5: C4ISR SS | J5: WAVE-1 | K5: David.Allen@SERCO-NA.COM | L5: Allen, David, E (Serco NA US)
A6: W1 | B6: https://serco.sharepoint.com/sites/Serco_Charleston_Shore | C6: SPO - M365 GROUP | D6: Owner | E6: Allen, David, E (Serco NA US) | F6: David.Allen@SERCO-NA.COM | G6: User | H6: SI2 | I6: C4ISR SS | J6: WAVE-1 | K6: David.Allen@SERCO-NA.COM | L6: Allen, David, E (Serco NA US)
A7: W1 | B7: https://serco.sharepoint.com/sites/Serco_Pensacola | C7: SPO - M365 GROUP | D7: Owner | E7: Allen, David, E (Serco NA US) | F7: David.Allen@SERCO-NA.COM | G7: User | H7: SI2 | I7: C4ISR SS | J7: WAVE-1 | K7: David.Allen@SERCO-NA.COM | L7: Allen, David, E (Serco NA US)
A8: W1 | B8: https://serco.sharepoint.com/sites/TravelHelp_PNS_CHS | C8: SPO - M365 GROUP | D8: Owner | E8: Allen, David, E (Serco NA US) | F8: David.Allen@SERCO-NA.COM | G8: User | H8: SI2 | I8: C4ISR SS | J8: WAVE-1 | K8: David.Allen@SERCO-NA.COM | L8: Allen, David, E (Serco NA US)
A9: W1 | B9: https://serco.sharepoint.com/sites/C4ISRSS | C9: TEAMS | D9: Owner | E9: Barnes, Gary (Serco NA US) | F9: Gary.Barnes@serco-na.com | G9: User | H9: SI2 | I9: SI2 | J9: WAVE-1 | K9: Gary.Barnes@serco-na.com | L9: Barnes, Gary (Serco NA US)
A10: W1 | B10: https://serco.sharepoint.com/sites/C4ISRSSTeamChannel-StaffCall | C10: SPO | D10: SiteCollectionAdmin | E10: Barnes, Gary (Serco NA US) | F10: Gary.Barnes@serco-na.com | G10: USER | H10: SI2 | I10: SI2 | J10: WAVE-1 | K10: Gary.Barnes@serco-na.com;Gary.Barnes@serco-na.com | L10: Barnes, Gary (Serco NA US)
A11: W1 | B11: https://serco.sharepoint.com/sites/FDICIFWMS | C11: TEAMS | D11: Owner | E11: Case, Dave, A (Serco NA US) | F11: David.Case@serco-na.com | G11: User | H11: SI2 | I11: Citizens Services | J11: WAVE-1 | K11: David.Case@serco-na.com | L11: Case, Dave, A (Serco NA US) | M11: Migrated in Wave 1B
A12: W1 | B12: https://serco.sharepoint.com/sites/FDICIFWMS-ProjectTeam | C12: SPO | D12: SiteCollectionAdmin | E12: Case, Dave, A (Serco NA US) | F12: David.Case@serco-na.com | G12: USER | H12: SI2 | I12: Citizens Services | J12: WAVE-1 | K12: David.Case@serco-na.com;David.Case@serco-na.com | L12: Case, Dave, A (Serco NA US)
A13: W1 | B13: https://serco.sharepoint.com/sites/ESSVIISampleTaskDwgReview | C13: TEAMS | D13: Owner | E13: Ceva, Ed, J (Serco NA US) | F13: Edward.Ceva@serco-na.com | G13: User | H13: SI2 | I13: C4ISR SS | J13: WAVE-1 | K13: Edward.Ceva@serco-na.com | L13: Ceva, Ed, J (Serco NA US)
A14: W1 | B14: https://serco.sharepoint.com/sites/ElPasoC5ISR | C14: TEAMS | D14: Owner | E14: Corey, Bob, W (Serco NA US) | F14: Robert.Corey@serco-na.com | G14: User | H14: SI2 | I14: C4ISR SS | J14: WAVE-1 | K14: Robert.Corey@serco-na.com | L14: Corey, Bob, W (Serco NA US)
A15: W1 | B15: https://serco.sharepoint.com/sites/IBD-SS | C15: SPO - M365 GROUP | D15: Owner | E15: Corey, Bob, W (Serco NA US) | F15: Robert.Corey@serco-na.com | G15: User | H15: SI2 | I15: C4ISR SS | J15: WAVE-1 | K15: Robert.Corey@serco-na.com | L15: Corey, Bob, W (Serco NA US)
A16: W1 | B16: https://serco.sharepoint.com/sites/ISEManagement-Ludlow | C16: TEAMS | D16: Owner | E16: Girard, Michael (Serco NA US) | F16: Michael.Girard@serco-na.com | G16: User | H16: SI2 | I16: SI2 | J16: WAVE-1 | K16: Michael.Girard@serco-na.com | L16: Girard, Michael (Serco NA US)
A17: W1 | B17: https://serco.sharepoint.com/sites/LCOMProgramManagementReview | C17: TEAMS | D17: Owner | E17: Girard, Michael (Serco NA US) | F17: Michael.Girard@serco-na.com | G17: User | H17: SI2 | I17: SI2 | J17: WAVE-1 | K17: Michael.Girard@serco-na.com | L17: Girard, Michael (Serco NA US)
A18: W1 | B18: https://serco.sharepoint.com/sites/SI2ProgramManagementReview | C18: TEAMS | D18: Owner | E18: Girard, Michael (Serco NA US) | F18: Michael.Girard@serco-na.com | G18: User | H18: SI2 | I18: SI2 | J18: WAVE-1 | K18: Michael.Girard@serco-na.com | L18: Girard, Michael (Serco NA US)
A19: W1 | B19: https://serco.sharepoint.com/sites/FETS | C19: SPO - M365 GROUP | D19: Owner | E19: Griffin, Chris (Serco NA US) | F19: Chris.Griffin@serco-na.com | G19: User | H19: SI2 | I19: SIE | J19: WAVE-1 | K19: Chris.Griffin@serco-na.com | L19: Griffin, Chris (Serco NA US)
A20: W1 | B20: https://serco.sharepoint.com/sites/FETSTEST | C20: SPO - M365 GROUP | D20: Owner | E20: Griffin, Chris (Serco NA US) | F20: Chris.Griffin@serco-na.com | G20: User | H20: SI2 | I20: SIE | J20: WAVE-1 | K20: Chris.Griffin@serco-na.com | L20: Griffin, Chris (Serco NA US)
A21: W1 | B21: https://serco.sharepoint.com/sites/KidsBenefits401K | C21: SPO - M365 GROUP | D21: Owner | E21: Guzman, Leonel (Serco NA US) | F21: Leonel.Guzman@serco-na.com | G21: User | H21: SI2 | I21: SSM-SCH | J21: WAVE-1 | K21: Leonel.Guzman@serco-na.com | L21: Guzman, Leonel (Serco NA US)
A22: W1 | B22: https://serco.sharepoint.com/sites/CYSCCTVPilotEngineeringIMCOM | C22: TEAMS | D22: Owner | E22: Harlow, Josh, G (Serco NA US) | F22: Joshua.Harlow@serco-na.com | G22: User | H22: SI2 | I22: C4ISR SS | J22: WAVE-1 | K22: Joshua.Harlow@serco-na.com | L22: Harlow, Josh, G (Serco NA US)
A23: W1 | B23: https://serco.sharepoint.com/sites/cys-engineers | C23: SPO - M365 GROUP | D23: Owner | E23: Harlow, Josh, G (Serco NA US) | F23: Joshua.Harlow@serco-na.com | G23: User | H23: SI2 | I23: C4ISR SS | J23: WAVE-1 | K23: Joshua.Harlow@serco-na.com | L23: Harlow, Josh, G (Serco NA US)
... A29: W1 | B29: https://serco.sharepoint.com/sites/ATFPGSCPSAC-EA | C29: SPO - M365 GROUP | D29: Owner | E29: Mcconnell, Joseph, J (Serco NA US) | F29: Joseph.Mcconnell@serco-na.com | G29: User | H29: SI2 | I29: C4ISR SS | J29: WAVE-1 | K29: Joseph.Mcconnell@serco-na.com | L29: Mcconnell, Joseph, J (Serco NA US)
A30: W1 | B30: https://serco.sharepoint.com/sites/CP22744USACEESSVII | C30: TEAMS | D30: Owner | E30: Mcconnell, Joseph, J (Serco NA US) | F30: Joseph.Mcconnell@serco-na.com | G30: User | H30: SI2 | I30: C4ISR SS | J30: WAVE-1 | K30: Joseph.Mcconnell@serco-na.com | L30: Mcconnell, Joseph, J (Serco NA US) | M30: ShareGate to migrate
A31: W1 | B31: https://serco.sharepoint.com/sites/EM2P | C31: TEAMS | D31: Owner | E31: Mcconnell, Joseph, J (Serco NA US) | F31: Joseph.Mcconnell@serco-na.com | G31: User | H31: SI2 | I31: C4ISR SS | J31: WAVE-1 | K31: Joseph.Mcconnell@serco-na.com | L31: Mcconnell, Joseph, J (Serco NA US)
A32: W1 | B32: https://serco.sharepoint.com/sites/JacksonvilleAE | C32: TEAMS | D32: Owner | E32: Mcconnell, Joseph, J (Serco NA US) | F32: Joseph.Mcconnell@serco-na.com | G32: User | H32: SI2 | I32: C4ISR SS | J32: WAVE-1 | K32: Joseph.Mcconnell@serco-na.com | L32: Mcconnell, Joseph, J (Serco NA US)
A33: W1 | B33: https://serco.sharepoint.com/sites/NIWCLant | C33: TEAMS | D33: Owner | E33: Mcconnell, Joseph, J (Serco NA US) | F33: Joseph.Mcconnell@serco-na.com | G33: User | H33: SI2 | I33: C4ISR SS | J33: WAVE-1 | K33: Joseph.Mcconnell@serco-na.com | L33: Mcconnell, Joseph, J (Serco NA US)
A34: W1 | B34: https://serco.sharepoint.com/sites/RegionN6RecompeteProposal | C34: TEAMS | D34: Owner | E34: Mcconnell, Joseph, J (Serco NA US) | F34: Joseph.Mcconnell@serco-na.com | G34: User | H34: SI2 | I34: C4ISR SS | J34: WAVE-1 | K34: Joseph.Mcconnell@serco-na.com | L34: Mcconnell, Joseph, J (Serco NA US)
A35: W1 | B35: https://serco.sharepoint.com/sites/911Engineering | C35: TEAMS | D35: Owner | E35: Mitchell, John, W (Serco NA US) | F35: John.Mitchell@serco-na.com | G35: User | H35: SI2 | I35: C4ISR SS | J35: WAVE-1 | K35: smankel@SERCO-NA.COM;John.Mitchell@serco-na.com | L35: Mitchell, John, W (Serco NA US)
A36: W1 | B36: https://serco.sharepoint.com/sites/C4ISRSSTeamChannel | C36: TEAMS | D36: Owner | E36: Mitchell, John, W (Serco NA US) | F36: John.Mitchell@serco-na.com | G36: User | H36: SI2 | I36: C4ISR SS | J36: WAVE-1 | K36: Gary.Barnes@serco-na.com;Joseph.Mcconnell@serco-na.com;John.Mitchell@serco-na.com | L36: Gary.Barnes@serco-na.com;Mitchell, John, W (Serco NA US)
A37: W1 | B37: https://serco.sharepoint.com/sites/Gate6Review | C37: TEAMS | D37: Owner | E37: Mitchell, John, W (Serco NA US) | F37: John.Mitchell@serco-na.com | G37: User | H37: SI2 | I37: C4ISR SS | J37: WAVE-1 | K37: John.Mitchell@serco-na.com | L37: Mitchell, John, W (Serco NA US)
A38: W1 | B38: https://serco.sharepoint.com/sites/ProposalCenter228-BigBlueIIIReport | C38: SPO | D38: SiteCollectionAdmin | E38: Mitchell, John, W (Serco NA US) | F38: John.Mitchell@serco-na.com | G38: USER | H38: SI2 | I38: C4ISR SS | J38: WAVE-1 | K38: John.Mitchell@serco-na.com;John.Mitchell@serco-na.com | L38: Mitchell, John, W (Serco NA US)
A39: W1 | B39: https://serco.sharepoint.com/sites/ProposalCenter228-CNSLID | C39: SPO | D39: SiteCollectionAdmin | E39: Mitchell, John, W (Serco NA US) | F39: John.Mitchell@serco-na.com | G39: USER | H39: SI2 | I39: C4ISR SS | J39: WAVE-1 | K39: John.Mitchell@serco-na.com;John.Mitchell@serco-na.com | L39: Mitchell, John, W (Serco NA US)
A40: W1 | B40: https://serco.sharepoint.com/sites/ProposalCenter228-TEAM | C40: SPO | D40: SiteCollectionAdmin | E40: Mitchell, John, W (Serco NA US) | F40: John.Mitchell@serco-na.com | G40: USER | H40: SI2 | I40: C4ISR SS | J40: WAVE-1 | K40: John.Mitchell@serco-na.com;John.Mitchell@serco-na.com | L40: Mitchell, John, W (Serco NA US)
A41: W1 | B41: https://serco.sharepoint.com/sites/PS2-EA | C41: TEAMS | D41: Owner | E41: Mitchell, John, W (Serco NA US) | F41: John.Mitchell@serco-na.com | G41: User | H41: SI2 | I41: C4ISR SS | J41: WAVE-1 | K41: smankel@SERCO-NA.COM;John.Mitchell@serco-na.com | L41: Mitchell, John, W (Serco NA US)
A42: W1 | B42: https://serco.sharepoint.com/sites/SBMProgramManagementReview | C42: TEAMS | D42: Owner | E42: Mitchell, John, W (Serco NA US) | F42: John.Mitchell@serco-na.com | G42: User | H42: SI2 | I42: C4ISR SS | J42: WAVE-1 | K42: Gary.Barnes@serco-na.com;John.Mitchell@serco-na.com | L42: Mitchell, John, W (Serco NA US)
... A56: W1 | B56: https://serco.sharepoint.com/sites/department | C56: SPO - M365 GROUP | D56: Owner | E56: Trail, Becky, L (Serco NA US) | F56: Becky.Trail@serco-na.com | G56: User | H56: SI2 | I56: C4ISR SS | J56: WAVE-1 | K56: Becky.Trail@serco-na.com | L56: Trail, Becky, L (Serco NA US)

Sheet Wave 2A
A1: Site Title | B1: Site URL | C1: RelationType | D1: DisplayName | E1: UserPrincipalName | F1: Active User | G1: Quest | H1: W2BUser | I1: Migrated | J1: Notes
A2: 2023 STEP Summer Interns | B2: https://serco.sharepoint.com/sites/2023STEPSummerInterns | C2: Owner | D2: Saben, Clark (Serco NA US) | E2: clark.saben@serco-na.com | F2: Member | G2: Mapped | H2: Yes | I2: Yes
A3: 2023 STEP Summer Interns | B3: https://serco.sharepoint.com/sites/2023STEPSummerInterns | C3: Owner | D3: Zhang, Max (Serco NA US) | E3: max.zhang@serco-na.com | F3: Member | G3: #N/A | H3: #N/A | I3: No
A4: AI de Camp | B4: https://serco.sharepoint.com/sites/AIdeCamp | C4: Owner | D4: Murphy, Travis, W (Serco NA US) | E4: travis.murphy@serco-na.com | F4: Member | G4: Mapped | H4: Yes | I4: Yes
A5: AI Proctor - AI Team | B5: https://serco.sharepoint.com/sites/AIProctor-AITeam | C5: Owner | D5: Bowden, James, A (Serco NA US) | E5: james.bowden@serco-na.com | F5: Member | G5: Mapped | H5: #N/A | I5: No
A6: AI Proctor - AI Team | B6: https://serco.sharepoint.com/sites/AIProctor-AITeam | C6: Owner | D6: Colony, Mike, J (Serco NA US) | E6: michael.colony@serco-na.com | F6: Member | G6: Mapped | H6: Yes | I6: Yes
A7: AI Proctor - AI Team | B7: https://serco.sharepoint.com/sites/AIProctor-AITeam | C7: Owner | D7: Davenport, Jack, H (Serco NA US) | E7: jack.davenport@serco-na.com | F7: Member | G7: Mapped | H7: Yes | I7: Yes
A8: AI Proctor - AI Team | B8: https://serco.sharepoint.com/sites/AIProctor-AITeam | C8: Owner | D8: Murphy, Travis, W (Serco NA US) | E8: travis.murphy@serco-na.com | F8: Member | G8: Mapped | H8: Yes | I8: Yes
A9: AI Proctor - AI Team | B9: https://serco.sharepoint.com/sites/AIProctor-AITeam | C9: Owner | D9: Rua, Rob, A (Serco NA US) | E9: robert.rua@serco-na.com | F9: Member | G9: Mapped | H9: Yes | I9: Yes
A10: AirUBW_sercoTeam | B10: https://serco.sharepoint.com/sites/AirUBW_sercoTeam | C10: Owner | D10: Smith, Dan, C (Serco NA US) | E10: daniel.c.smith@serco-na.com | F10: Member | G10: Mapped | H10: Yes | I10: Yes
A11: Air U Initiatives | B11: https://serco.sharepoint.com/sites/AirUInitiatives | C11: Owner | D11: Martin, Jonathan, L (Serco NA US) | E11: jonathan.l.martin@serco-na.com | F11: Member | G11: Mapped | H11: #N/A | I11: No
A12: Air U Initiatives | B12: https://serco.sharepoint.com/sites/AirUInitiatives | C12: Owner | D12: Owens, Gregory (Serco NA US) | E12: gregory.owens@serco-na.com | F12: Member | G12: Migrated | H12: #N/A | I12: Yes
A13: Air U Initiatives | B13: https://serco.sharepoint.com/sites/AirUInitiatives | C13: Owner | D13: Smith, Dan, C (Serco NA US) | E13: daniel.c.smith@serco-na.com | F13: Member | G13: Mapped | H13: Yes | I13: Yes
A14: Alfonso PM Task Board | B14: https://serco.sharepoint.com/sites/AlfonsoPMTaskBoard | C14: Owner | D14: Gomez, Alfonso, N (Serco NA US) | E14: alfonso.gomez@serco-na.com | F14: Member | G14: Mapped | H14: Yes | I14: Yes
A15: Chatbot | B15: https://serco.sharepoint.com/sites/AlfonsosTasks | C15: Owner | D15: Gomez, Alfonso, N (Serco NA US) | E15: alfonso.gomez@serco-na.com | F15: Member | G15: Mapped | H15: Yes | I15: Yes
A16: ATG All Hands | B16: https://serco.sharepoint.com/sites/ATGAllHands | C16: Owner | D16: Davenport, Jack, H (Serco NA US) | E16: jack.davenport@serco-na.com | F16: Member | G16: Mapped | H16: Yes | I16: Yes
A17: ATG All Hands | B17: https://serco.sharepoint.com/sites/ATGAllHands | C17: Owner | D17: Durham, Debra, S (Serco NA US) | E17: debra.s.durham@serco-na.com | F17: Member | G17: Migrated | H17: #N/A | I17: Yes
A18: ATG - Chatbot - Project Space | B18: https://serco.sharepoint.com/sites/ATG-Chatbot-ProjectSpace | C18: Owner | D18: Gomez, Alfonso, N (Serco NA US) | E18: alfonso.gomez@serco-na.com | F18: Member | G18: Mapped | H18: Yes | I18: Yes
A19: ATG - Chatbot Team | B19: https://serco.sharepoint.com/sites/ATG-ChatbotTeam | C19: Owner | D19: Gomez, Alfonso, N (Serco NA US) | E19: alfonso.gomez@serco-na.com | F19: Member | G19: Mapped | H19: Yes | I19: Yes
A20: ATG Knowledge Share | B20: https://serco.sharepoint.com/sites/ATGKnowledgeShare | C20: Owner | D20: Colony, Mike, J (Serco NA US) | E20: michael.colony@serco-na.com | F20: Member | G20: Mapped | H20: Yes | I20: Yes
A21: ATG Knowledge Share | B21: https://serco.sharepoint.com/sites/ATGKnowledgeShare | C21: Owner | D21: Murphy, Travis, W (Serco NA US) | E21: travis.murphy@serco-na.com | F21: Member | G21: Mapped | H21: Yes | I21: Yes
A22: ATG Knowledge Share | B22: https://serco.sharepoint.com/sites/ATGKnowledgeShare | C22: Owner | D22: Rua, Rob, A (Serco NA US) | E22: robert.rua@serco-na.com | F22: Member | G22: Mapped | H22: Yes | I22: Yes
A23: Growth Automation Project | B23: https://serco.sharepoint.com/sites/BDAutomationProject | C23: Owner | D23: Gomez, Alfonso, N (Serco NA US) | E23: alfonso.gomez@serco-na.com | F23: Member | J23: Added 5/26
A24: BD Automation Project | B24: https://serco.sharepoint.com/sites/BI-AID | C24: Owner | D24: Gomez, Alfonso, N (Serco NA US) | E24: alfonso.gomez@serco-na.com | F24: Member | G24: Mapped | H24: Yes | I24: Yes
A25: Chatbot | B25: https://serco.sharepoint.com/sites/Chatbot | C25: Owner | D25: Davenport, Jack, H (Serco NA US) | E25: jack.davenport@serco-na.com | F25: Member | G25: Mapped | H25: Yes | I25: Yes
A26: Chatbot | B26: https://serco.sharepoint.com/sites/Chatbot | C26: Owner | D26: Fetz, Ryan (Serco NA US) | E26: ryan.fetz@serco-na.com | F26: Member | G26: Mapped | H26: Yes | I26: Yes
A27: Covan - Serco | B27: https://serco.sharepoint.com/sites/Covan-Serco | C27: Owner | D27: Chang, Yow-Ren (Serco NA) | E27: yowren.chang@serco-na.com | F27: Member | G27: Mapped | H27: Yes | I27: Yes
A28: Data Platform | B28: https://serco.sharepoint.com/sites/DataPlatformPOC | C28: Owner | D28: Bowden, James, A (Serco NA US) | E28: james.bowden@serco-na.com | F28: Member | G28: Mapped | H28: #N/A | I28: No
A29: Data Platform | B29: https://serco.sharepoint.com/sites/DataPlatformPOC | C29: Owner | D29: Olson, Miles, C (Serco NA US) | E29: miles.olson@serco-na.com | F29: Member | G29: Migrated | H29: #N/A | I29: Yes
A30: Data Platform | B30: https://serco.sharepoint.com/sites/DataPlatformPOC | C30: Owner | D30: Roffman, Samuel (Serco NA US) | E30: samuel.roffman@serco-na.com | F30: Member | G30: Mapped | H30: Yes | I30: Yes
A31: Data Platform | B31: https://serco.sharepoint.com/sites/DataPlatformPOC | C31: Owner | D31: Rojas, Alex, K (Serco NA) | E31: alex.rojas@serco-na.com | F31: Member | G31: Migrated | H31: #N/A | I31: Yes
A32: Data Platform | B32: https://serco.sharepoint.com/sites/DataPlatformPOC | C32: Owner | D32: Smith, Dan, C (Serco NA US) | E32: daniel.c.smith@serco-na.com | F32: Member | G32: Mapped | H32: Yes | I32: Yes
A33: EKB PVT and Test Automation | B33: https://serco.sharepoint.com/sites/EKBPVTandTestAutomation | C33: Owner | D33: Gomez, Alfonso, N (Serco NA US) | E33: alfonso.gomez@serco-na.com | F33: Member | J33: Added 5/26
A34: GAiT - Ai-Powered Business Development | B34: https://serco.sharepoint.com/sites/gait-ai-poweredbusinessdevelopment | C34: Owner | D34: Gomez, Alfonso, N (Serco NA US) | E34: alfonso.gomez@serco-na.com | F34: Member | J34: Added 5/26
A35: Serco PPM Home | B35: https://serco.sharepoint.com/sites/GLB-GB-PDCLIPWA-PJ | C35: AssociatedOwnersGroup | D35: o-bsabir | E35: o-bsabir@serco-na.com | F35: Member | G35: Mapped | H35: #N/A | I35: No | J35: Removed 5/26. Owners not in Wave2A users dataset.
A36: Serco PPM Home | B36: https://serco.sharepoint.com/sites/GLB-GB-PDCLIPWA-PJ | C36: AssociatedOwnersGroup | D36: Sabir, Bureera (Serco NA US) | E36: bureera.sabir@serco-na.com | F36: Member | G36: Mapped | H36: #N/A | I36: No | J36: Removed 5/26. Owners not in Wave2A users dataset.
A37: Growth Automation Tool User Support | B37: https://serco.sharepoint.com/sites/GrowthAutomationToolUserSupport | C37: Owner | D37: Davenport, Jack, H (Serco NA US) | E37: jack.davenport@serco-na.com | F37: Member | G37: Mapped | H37: Yes | I37: Yes | J37: Added 5/26
A38: Growth Automation Tool User Support | B38: https://serco.sharepoint.com/sites/GrowthAutomationToolUserSupport | C38: Owner | D38: Gomez, Alfonso, N (Serco NA US) | E38: alfonso.gomez@serco-na.com | F38: Member | J38: Added 5/26
A39: GSA AI Acquisition System RFI Opportunity | B39: https://serco.sharepoint.com/sites/GSAAIAcquisitionSystemRFIOpportunity | C39: Owner | D39: Cormack, Kyle (Serco NA US) | E39: kyle.cormack@serco-na.com | J39: Added 5/26
A40: GSA AI Acquisition System RFI Opportunity | B40: https://serco.sharepoint.com/sites/GSAAIAcquisitionSystemRFIOpportunity | C40: Owner | D40: Davenport, Jack, H (Serco NA US) | E40: jack.davenport@serco-na.com | F40: Member | G40: Mapped | H40: Yes | I40: Yes | J40: Added 5/26
...

Sheet Wave 2B
A1: Site Url | B1: Site Name | C1: Is Teams Site | D1: W1Granular | E1: W2Granular | F1: Registry
A2: https://serco.sharepoint.com/sites/0623-2025PSIUSSFPJDDG121 | B2: 0623-2025 PSI USS FPJ DDG121 | C2: FALSE | D2: No | E2: No | F2: #N/A
A3: https://serco.sharepoint.com/sites/22464-USSCC4I | B3: 22464-USSC C4I | C3: FALSE | D3: YES | E3: No | F3: #N/A
A4: https://serco.sharepoint.com/sites/3PDtrackerwJim | B4: 3PD tracker w/Jim | C4: FALSE | D4: YES | E4: No | F4: #N/A
A5: https://serco.sharepoint.com/sites/3rdPartyDamage | B5: 3rd Party Damage | C5: FALSE | D5: YES | E5: No | F5: #N/A
A6: https://serco.sharepoint.com/sites/70 | B6: 70 | C6: FALSE | D6: No | E6: YES | F6: #N/A
A7: https://serco.sharepoint.com/sites/911Engineering | B7: 911 Engineering | C7: TRUE | D7: YES | E7: No | F7: #N/A
A8: https://serco.sharepoint.com/sites/ADNSCANESNetworkEngineering | B8: ADNS/CANES Network Engineering | C8: TRUE | D8: No | E8: No | F8: #N/A
A9: https://serco.sharepoint.com/sites/AEEnclaveTeam | B9: AE Enclave Team | C9: FALSE | D9: YES | E9: No | F9: #N/A
A10: https://serco.sharepoint.com/sites/AIENEXT | B10: AIE NEXT | C10: TRUE | D10: No | E10: No | F10: #N/A
A11: https://serco.sharepoint.com/sites/AMAS_CYBER | B11: AMAS_CYBER | C11: TRUE | D11: No | E11: No | F11: #N/A
A12: https://serco.sharepoint.com/sites/ATFP | B12: GSC Proposals | C12: TRUE | D12: YES | E12: No | F12: #N/A
A13: https://serco.sharepoint.com/sites/ATFPBridgeSustainment | B13: Goebel - Sustainment Team | C13: TRUE | D13: YES | E13: No | F13: #N/A
A14: https://serco.sharepoint.com/sites/ATFPBridgeTickets | B14: ATFP Bridge Tickets | C14: FALSE | D14: YES | E14: No | F14: #N/A
A15: https://serco.sharepoint.com/sites/ATFPGSCAMAS | B15: ATFP GSC AMAS | C15: FALSE | D15: No | E15: No | F15: #N/A
A16: https://serco.sharepoint.com/sites/ATFPGSCContractCommunication | B16: ATFP GSC Contract Communication | C16: FALSE | D16: No | E16: No | F16: #N/A
A17: https://serco.sharepoint.com/sites/ATFPGSCENERMS | B17: ATFP GSC ENERMS | C17: FALSE | D17: No | E17: No | F17: #N/A
A18: https://serco.sharepoint.com/sites/ATFPGSCGBRS | B18: ATFP GSC GBRS | C18: FALSE | D18: YES | E18: No | F18: #N/A
... A276: https://serco.sharepoint.com/sites/WorkforceProposalData | B276: Workforce Proposal Data | C276: TRUE | D276: YES | E276: No | F276: #N/A

Sheet DoNotMigrate-W1
A1: SITE URL (MAIN) | B1: SIZE IN GB | C1: SITE OWNERS - EMAIL | D1: BU | E1: Portfolio | F1: Action | G1: Site Exist in GCCH? | H1: Teams
A2: https://serco.sharepoint.com/sites/EHSINSIGHT | C2: jmorrison@SERCO-NA.COM | D2: SI2 | E2: SSM-PMO
A3: https://serco.sharepoint.com/sites/EHSINSIGHT-AdminPrivateChannel | C3: jmorrison@serco-na.com | D3: SI2 | E3: SSM-PMO
A4: https://serco.sharepoint.com/sites/EHSInsightImplimentation | C4: jmorrison@SERCO-NA.COM | D4: SI2 | E4: SSM-PMO
A5: https://serco.sharepoint.com/sites/EHSInsightImplimentation-SpendPlan | C5: jmorrison@serco-na.com | D5: SI2 | E5: SSM-PMO
A6: https://serco.sharepoint.com/sites/ehsinsighttraining | C6: jmorrison@SERCO-NA.COM | D6: SI2 | E6: SSM-PMO
A7: https://serco.sharepoint.com/sites/EHSINSIGHT-TrainingModule | C7: jmorrison@serco-na.com | D7: SI2 | E7: SSM-PMO
A8: https://serco.sharepoint.com/sites/GrandForksADP2 | B8: 0 | C8: Randy.Brown@serco-na.com | D8: Corporate Services | E8: Technology | F8: Do NOT Migrate
A9: https://serco.sharepoint.com/sites/MilesOlson2 | B9: 0.01 | C9: Miles.Olson@serco-na.com | D9: Corporate Services | E9: Technology | F9: Do NOT Migrate
A10: https://serco.sharepoint.com/sites/MilesOlsonSite1 | B10: 0.01 | C10: Miles.Olson@serco-na.com | D10: Corporate Services | E10: Technology | F10: Do NOT Migrate
A11: https://serco.sharepoint.com/sites/PersonalTest2 | B11: 0.01 | C11: Zoe.Tran@serco-na.com | D11: Corporate Services | E11: Technology | F11: Do NOT Migrate
A12: https://serco.sharepoint.com/sites/PracticeSite | B12: 0.01 | C12: Miles.Olson@serco-na.com | D12: Corporate Services | E12: Technology | F12: Do NOT Migrate
A13: https://serco.sharepoint.com/sites/PracticeSite16 | B13: 0.01 | C13: Miles.Olson@serco-na.com | D13: Corporate Services | E13: Technology | F13: Do NOT Migrate
A14: https://serco.sharepoint.com/sites/TestSite20 | B14: 0.01 | C14: Zoe.Tran@serco-na.com | D14: Corporate Services | E14: Technology | F14: Do NOT Migrate
A15: https://serco.sharepoint.com/sites/BDOpportunityTracker | B15: 0.01 | C15: Whitney.Sessoms@SERCO-NA.COM | D15: Corporate Services | E15: Technology | F15: Do NOT Migrate
A16: https://serco.sharepoint.com/sites/C3BMT | B16: 0.01 | C16: Kevin.Pratte@serco-na.com | D16: Corporate Services | E16: Technology | F16: Do NOT Migrate
A17: https://serco.sharepoint.com/sites/Carp3 | B17: 0.01 | C17: Thomas.Glass@serco-na.com | D17: Corporate Services | E17: Technology | F17: Do NOT Migrate
A18: https://serco.sharepoint.com/sites/EmployeeEngagementProgram-PatuxentRiver | B18: 0.01 | C18: Robin.Landeros@serco-na.com | D18: Corporate Services | E18: Technology | F18: Do NOT Migrate
A19: https://serco.sharepoint.com/sites/ETSSOrg | B19: 0.01 | C19: Kelly.Cormican@serco-na.com | D19: Corporate Services | E19: Technology | F19: Do NOT Migrate
... A32: https://serco.sharepoint.com/sites/SWBBSchedulers | B32: 0.01 | C32: Teresa.Burke@serco-na.com | D32: Corporate Services | E32: Technology | F32: Do NOT Migrate
A33: https://serco.sharepoint.com/sites/ABMSArchitectureTeam | B33: 0.01 | C33: Preston.White@serco-na.com | D33: Corporate Services | E33: #N/A | F33: Do NOT Migrate
A34: https://serco.sharepoint.com/sites/AFRCCI2RFI | B34: 0.01 | C34: Luke.Mcdade@serco-na.com | D34: Corporate Services | E34: Technology | F34: Do NOT Migrate
A35: https://serco.sharepoint.com/sites/AgileImpactMissionPerformanceOptimizationTeam | B35: 0.01 | C35: Albert.Moseley@serco-na.com | D35: Corporate Services | E35: Technology | F35: Do NOT Migrate
A36: https://serco.sharepoint.com/sites/ArmyReview | B36: 0.01 | C36: Brian.Stehle@serco-na.com | D36: Corporate Services | E36: Technology | F36: Do NOT Migrate
A37: https://serco.sharepoint.com/sites/ATGandIDIQCollaborationSite | B37: 0.01 | C37: Tracy.West@serco-na.com | D37: Corporate Services | E37: Technology | F37: Do NOT Migrate
A38: https://serco.sharepoint.com/sites/CGBI | B38: 0.01 | C38: Gus.Burnette@serco-na.com | D38: Corporate Services | E38: Technology | F38: Do NOT Migrate
A39: https://serco.sharepoint.com/sites/DashboardDevelopment | B39: 0.01 | C39: Brian.Godfrey@serco-na.com | D39: Corporate Services | E39: Technology | F39: Do NOT Migrate
A40: https://serco.sharepoint.com/sites/DataCollectionYellowBeltProject | B40: 0.01 | C40: Brian.Godfrey@serco-na.com | D40: Corporate Services | E40: Technology | F40: Do NOT Migrate
A41: https://serco.sharepoint.com/sites/DeploymentHealthResearchSupportServicessections3.4and3.5 | B41: 0.01 | C41: Scott.Adams@serco-na.com | D41: Corporate Services | E41: Technology | F41: Do NOT Migrate
A42: https://serco.sharepoint.com/sites/FAR-RFOCompare | B42: 0.01 | C42: Christine.Diehl@serco-na.com | D42: Corporate Services | E42: Technology | F42: Do NOT Migrate
A43: https://serco.sharepoint.com/sites/GayleSpace | B43: 0.01 | C43: Gayle.Ingram@serco-na.com | D43: Corporate Services | E43: Technology | F43: Do NOT Migrate
A44: https://serco.sharepoint.com/sites/KC-YBCASchedule | B44: 0.01 | C44: Brian.Godfrey@serco-na.com | D44: Corporate Services | E44: Technology | F44: Do NOT Migrate
A45: https://serco.sharepoint.com/sites/LAWBurnPlan | B45: 0.01 | C45: Brian.Stehle@serco-na.com; Timothy.Baker@serco-na.com | D45: Corporate Services | E45: #N/A | F45: Do NOT Migrate
A46: https://serco.sharepoint.com/sites/PIO-Sandbox | B46: 0.01 | C46: Zoe.Tran@serco-na.com | D46: Corporate Services | E46: Technology | F46: Do NOT Migrate
A47: https://serco.sharepoint.com/sites/PMA-226Opportunity | B47: 0.01 | C47: Thomas.Glass@serco-na.com; Wayne.Borchers@serco-na.com | D47: Corporate Services | E47: #N/A | F47: Do NOT Migrate
A48: https://serco.sharepoint.com/sites/PNTSDUE | B48: 0.01 | C48: Bradley.Schlenker@serco-na.com | D48: Corporate Services | E48: Technology | F48: Do NOT Migrate
A49: https://serco.sharepoint.com/sites/ReformedPCOs | B49: 0.01 | C49: Christina.Hall@serco-na.com | D49: Corporate Services | E49: Technology | F49: Do NOT Migrate
A50: https://serco.sharepoint.com/sites/SAM-US-METS-DON-PIO_IMS-MTM | B50: 0.01 | C50: Cassidy.Kuzemka@serco-na.com | D50: Corporate Services | E50: Technology | F50: Do NOT Migrate
A51: https://serco.sharepoint.com/sites/SECOIA | B51: 0.01 | C51: George.Sanderlin@serco-na.com | D51: Corporate Services | E51: Technology | F51: Do NOT Migrate
A52: https://serco.sharepoint.com/sites/SercoWBBConsultingFileTransfer | B52: 0.01 | C52: Albert.Moseley@serco-na.com | D52: Corporate Services | E52: Technology | F52: Do NOT Migrate
...

Sheet All Sites_20260129180943356
A1: ﻿"Site name" | B1: , | C1: Teams | D1: Channel sites | E1: IBMode | F1: Storage used (GB) | G1: Primary admin | H1: Hub | I1: Template | J1: Last activity (UTC) | K1: Date created | L1: Created by | M1: Storage limit (GB) | N1: Storage used (%) | O1: Microsoft 365 group | P1: Files viewed or edited | Q1: Page views | R1: Page visits | S1: Files | T1: Sensitivity | U1: External sharing | V1: Wave
A2: 0 | B2: https://serco.sharepoint.com/sites/00000 | C2: TRUE | E2: Open | F2: 0.01 | I2: Team site | K2: 44222.585 | L2: 00000 Owners | M2: 25600 | N2: 0 | O2: TRUE | P2: 0 | Q2: 0 | R2: 0 | S2: 16 | U2: On | V2: Unplanned
A3: 70 | B3: https://serco.sharepoint.com/sites/70 | C3: FALSE | E3: Open | F3: 0 | I3: Team site | J3: 45947 | K3: 43651.66 | L3: Kitchin, Todd, M (Serco NA US) | M3: 25600 | N3: 0 | O3: TRUE | P3: 0 | Q3: 0 | R3: 0 | S3: 132 | U3: On | V3: Unplanned
A4: 99 | B4: https://serco.sharepoint.com/sites/99 | C4: FALSE | E4: Open | F4: 0.02 | I4: Team site | J4: 44490 | K4: 44412.857 | L4: 99 Owners | M4: 25600 | N4: 0 | O4: TRUE | P4: 0 | Q4: 0 | R4: 0 | S4: 14 | U4: On | V4: Unplanned
A5: 123 | B5: https://serco.sharepoint.com/sites/1234 | C5: TRUE | E5: Open | F5: 0.05 | I5: Team site | J5: 45742 | K5: 44239.434 | L5: 123 Owners | M5: 25600 | N5: 0 | O5: TRUE | P5: 0 | Q5: 0 | R5: 0 | S5: 21 | U5: On | V5: Unplanned
A6: 397 | B6: https://serco.sharepoint.com/sites/397 | C6: FALSE | E6: Open | F6: 0 | I6: Team site | K6: 45967.742 | L6: 397 Owners | M6: 25600 | N6: 0 | O6: TRUE | P6: 0 | Q6: 0 | R6: 0 | S6: 0 | U6: On | V6: Unplanned
A7: 401 | B7: https://serco.sharepoint.com/sites/401 | C7: TRUE | E7: Open | F7: 0 | I7: Team site | J7: 45692 | K7: 45442.495 | L7: 401 Owners | M7: 25600 | N7: 0 | O7: TRUE | P7: 0 | Q7: 0 | R7: 0 | S7: 7 | U7: On | V7: Unplanned
A8: 2018 | B8: https://serco.sharepoint.com/sites/2018 | C8: FALSE | E8: Open | F8: 0.01 | I8: Team site | J8: 43916 | K8: 43313.554 | L8: Castledine, Annabel | M8: 25600 | N8: 0 | O8: TRUE | P8: 0 | Q8: 0 | R8: 0 | S8: 39 | U8: On | V8: Unplanned
A9: 21585 | B9: https://serco.sharepoint.com/sites/21585 | C9: FALSE | E9: Open | F9: 0.01 | I9: Team site | K9: 44310.083 | L9: 21585 Owners | M9: 25600 | N9: 0 | O9: TRUE | P9: 0 | Q9: 0 | R9: 0 | S9: 15 | U9: On | V9: Unplanned
A10: 44624 | B10: https://serco.sharepoint.com/sites/03042022 | C10: FALSE | E10: Open | F10: 0 | I10: Team site | K10: 44653.739 | L10: 03/04/2022 Owners | M10: 25600 | N10: 0 | O10: TRUE | P10: 0 | Q10: 0 | R10: 0 | S10: 8 | U10: On | V10: Unplanned
A11: 44625 | B11: https://serco.sharepoint.com/sites/030522 | C11: FALSE | E11: Open | F11: 0 | I11: Team site | K11: 44684.244 | L11: 03/05/22 Owners | M11: 25600 | N11: 0 | O11: TRUE | P11: 0 | Q11: 0 | R11: 0 | S11: 8 | U11: On | V11: Unplanned
A12: 44627 | B12: https://serco.sharepoint.com/sites/03072022 | C12: FALSE | E12: Open | F12: 0 | I12: Team site | K12: 44744.677 | L12: 03/07/2022 Owners | M12: 25600 | N12: 0 | O12: TRUE | P12: 0 | Q12: 0 | R12: 0 | S12: 8 | U12: On | V12: Unplanned
A13: 46287 | B13: https://serco.sharepoint.com/sites/September2022 | C13: FALSE | E13: Open | F13: 0.01 | I13: Team site | J13: 44825 | K13: 44789.541 | L13: September 2022 Owners | M13: 25600 | N13: 0 | O13: TRUE | P13: 0 | Q13: 0 | R13: 0 | S13: 13 | U13: On | V13: Unplanned
A14: 60031 | B14: https://serco.sharepoint.com/sites/60031 | C14: FALSE | E14: Open | F14: 0.01 | I14: Team site | K14: 44139.582 | L14: Hendricks, Patsy, A (Serco NA) | M14: 25600 | N14: 0 | O14: TRUE | P14: 0 | Q14: 0 | R14: 0 | S14: 18 | U14: On | V14: Unplanned
A15: Defense Services Business Unit | B15: https://serco.sharepoint.com/sites/SAM-US-DefSerBU-FT | C15: FALSE | E15: Open | F15: 0.03 | G15: System Account | I15: Team site (classic experience) | J15: 45866 | K15: 42429.647 | L15: System Account | M15: 25600 | N15: 0 | O15: FALSE | P15: 0 | Q15: 0 | R15: 0 | S15: 159 | U15: Off | V15: Unplanned
A16: !Finance Home Team Theo Teams Site | B16: https://serco.sharepoint.com/sites/FinanceHomeTeamTheoTeamsSite | C16: TRUE | E16: Open | F16: 0.02 | I16: Team site | J16: 45903 | K16: 45707.799 | L16: !Finance Home Team Theo Teams Site Owners | M16: 25600 | N16: 0 | O16: TRUE | P16: 0 | Q16: 0 | R16: 0 | S16: 11 | U16: On | V16: Unplanned
A17: #TeamC&W | B17: https://serco.sharepoint.com/sites/TeamCW | C17: TRUE | E17: Open | F17: 0.01 | I17: Team site | J17: 45979 | K17: 43910.353 | L17: Harrison, Linda | M17: 25600 | N17: 0 | O17: TRUE | P17: 0 | Q17: 0 | R17: 0 | S17: 23 | U17: On | V17: Unplanned
A18: (DO NOT USE) OLD Trust Room Booking | B18: https://serco.sharepoint.com/sites/TrustRoomBooking | C18: TRUE | E18: Open | F18: 0.28 | I18: Team site | J18: 44472 | K18: 43911.383 | L18: Marlow, Martin | M18: 25600 | N18: 0 | O18: TRUE | P18: 0 | Q18: 0 | R18: 0 | S18: 43 | U18: On | V18: Unplanned
A19: (USAF21001.00) | B19: https://serco.sharepoint.com/sites/WBBProjects | C19: FALSE | E19: Open | F19: 0 | G19: o-fkruk | I19: Team site (no Microsoft 365 group) | J19: 45482 | K19: 44887.801 | L19: o-jtinsley | M19: 25600 | N19: 0 | O19: FALSE | P19: 0 | Q19: 0 | R19: 0 | S19: 6 | U19: Off | V19: Unplanned
