Workbook

Sheet Agile1BSites
A1: SITE Name | B1: SITE URL (MAIN) | C1: TARGET URL | D1: SITE OWNERS - EMAIL | E1: BU | F1: Portfolio | G1: Wave | H1: Action | I1: Wave 1B Status | J1: Site Exist in GCCH?
A2: AAAA | B2: https://serco.sharepoint.com/sites/aaaa | C2: https://serconagcch.sharepoint.us/sites/aaaa | D2: Michael.J.Harris@serco-na.com | E2: Corporate Services | F2: Technology | G2: Wave 1B | H2: Migrate | I2: Sync Started
A3: AAAAPlanning | B3: https://serco.sharepoint.com/sites/aaaaplanning | C3: https://serconagcch.sharepoint.us/sites/aaaaplanning | D3: Michael.J.Harris@serco-na.com | E3: Corporate Services | F3: Technology | G3: Wave 1B | H3: Migrate | I3: Sync Started
A4: Acquisition Management (AQM) | B4: https://serco.sharepoint.com/sites/AFSFMarketTeam | D4: Raymond.Wier@serco-na.com | E4: Corporate Services | F4: Technology | G4: Wave 1B | H4: Migrate | I4: ShareGate - connected | J4: https://gov.teams.microsoft.us/l/team/19%3Agcch%3Af9f705e178ae4d588e8f42e0406241f8%40thread.tacv2/conversations?groupId=d95aa34f-d2f3-4d7e-a0ab-ed6d7d8c8d22&tenantId=fb1f5cc5-be84-4881-b037-2d641aea97fd
A5: Acquisition Management (AQM)-AUiX | B5: https://serco.sharepoint.com/sites/AFSFMarketTeam-AUiXBriefing | D5: Raymond.Wier@serco-na.com | E5: Corporate Services | F5: Technology | G5: Wave 1B | H5: Migrate | I5: See above - connected
A6: Acquisition Management (AQM)-RS3 PM PNT PSS VP 31231 | B6: https://serco.sharepoint.com/sites/AFSFMarketTeam-RS3PMPNTPSSVP31231 | D6: Raymond.Wier@serco-na.com | E6: Corporate Services | F6: Technology | G6: Wave 1B | H6: Migrate | I6: See above - connected
A7: Acquisition Management (AQM)-Training | B7: https://serco.sharepoint.com/sites/AFSFMarketTeam-Training | D7: Raymond.Wier@serco-na.com | E7: Corporate Services | F7: Technology | G7: Wave 1B | H7: Migrate | I7: See above - connected
A8: Acquisition Management (AQM)-USSF Training | B8: https://serco.sharepoint.com/sites/AFSFMarketTeam-USSFTraining | D8: Raymond.Wier@serco-na.com | E8: Corporate Services | F8: Technology | G8: Wave 1B | H8: Migrate | I8: See above - connected
A9: WRO Team | B9: https://serco.sharepoint.com/sites/AFWROSpecialProjects | C9: https://serconagcch.sharepoint.us/sites/AFWROSpecialProjects | D9: Raymond.Wier@serco-na.com | E9: Corporate Services | F9: Technology | G9: Wave 1B | H9: Migrate | I9: Sync Started-connected
A10: WRO Team-HBG Special Projects 2 | B10: https://serco.sharepoint.com/sites/AFWROSpecialProjects-HBGSpecialProjects2 | C10: https://serconagcch.sharepoint.us/sites/AFWROSpecialProjects | I10: Sync Started-connected
A11: WRO Team-37025 programmatics | B11: https://serco.sharepoint.com/sites/AFWROSpecialProjects-programatics | C11: https://serconagcch.sharepoint.us/sites/AFWROSpecialProjects | D11: James.Mathis@serco-na.com | E11: Corporate Services | F11: Technology | G11: Wave 1B | H11: Migrate | I11: Sync Started-connected
A12: AHFRM | B12: https://serco.sharepoint.com/sites/ahfrm | C12: https://serconagcch.sharepoint.us/sites/ahfrm | D12: Raymond.Wier@serco-na.com | E12: Corporate Services | F12: Technology | G12: Wave 1B | H12: Migrate | I12: Sync Started
A13: AHFRM Rapid Fielding Planning and Support-AHFRM DTIC Management Channel | B13: https://serco.sharepoint.com/sites/AHFRMDTICKICKOFF-AHFRMDTICManagementChannel | C13: https://serconagcch.sharepoint.us/sites/AHFRMDTICKICKOFF | D13: Steven.Yelverton@serco-na.com | E13: Corporate Services | F13: Technology | G13: Wave 1B | H13: Migrate | I13: Sync Started
A14: AHFRM Manufacturing Emails | B14: https://serco.sharepoint.com/sites/AHFRMManufacturingEmails | C14: https://serconagcch.sharepoint.us/sites/AHFRMManufacturingEmails | D14: Brian.Townsend@serco-na.com | E14: Corporate Services | F14: Technology | G14: Wave 1B | H14: Migrate | I14: Sync Started
A15: AmeriCorps Workforce Analysis | B15: https://serco.sharepoint.com/sites/AmeriCorpsWorkforceAnalysis | C15: https://serconagcch.sharepoint.us/sites/AmeriCorpsWorkforceAnalysis | D15: Allison.Gervasio@serco-na.com | E15: Corporate Services | F15: Technology | G15: Wave 1B | H15: Migrate | I15: Sync Started
A16: Angelo B-52 Files | B16: https://serco.sharepoint.com/sites/AngeloFiles | C16: https://serconagcch.sharepoint.us/sites/AngeloFiles | D16: Brian.Townsend@serco-na.com | E16: Corporate Services | F16: Technology | G16: Wave 1B | H16: Migrate | I16: Sync Started
A17: Armed Overwatch | B17: https://serco.sharepoint.com/sites/ArmedOverwatch | C17: https://serconagcch.sharepoint.us/sites/ArmedOverwatch | D17: Gary.Leavy@serco-na.com | E17: Corporate Services | F17: Technology | G17: Wave 1B | H17: Migrate | I17: Sync Started
A18: Army CONOPS Team | B18: https://serco.sharepoint.com/sites/ArmyCONOPSTeam | C18: https://serconagcch.sharepoint.us/sites/ArmyCONOPSTeam | D18: Jay.Voorhees@serco-na.com | E18: Corporate Services | F18: Technology | G18: Wave 1B | H18: Migrate | I18: Sync Started
A19: Army Team | B19: https://serco.sharepoint.com/sites/armyteam | C19: https://serconagcch.sharepoint.us/sites/armyteam | D19: Michael.J.Harris@serco-na.com | E19: Corporate Services | F19: Technology | G19: Wave 1B | H19: Migrate | I19: Sync Started
A20: AUSA Group | B20: https://serco.sharepoint.com/sites/AUSAGroup | C20: https://serconagcch.sharepoint.us/sites/AUSAGroup | D20: Michael.J.Harris@serco-na.com | E20: Corporate Services | F20: Technology | G20: Wave 1B | H20: Migrate | I20: Sync Started
A21: B-52 DTIC IAC Team | B21: https://serco.sharepoint.com/sites/B-52DTICIACTeam | C21: https://serconagcch.sharepoint.us/sites/B-52DTICIACTeam | D21: Brian.Townsend@serco-na.com | E21: Corporate Services | F21: Technology | G21: Wave 1B | H21: Migrate | I21: Sync Started | J21: https://gov.teams.microsoft.us/l/channel/19%3Agcch%3Ad84581d74cd642a2a5d7289286422301%40thread.tacv2/31688%20B-52%20Analysis%20and%20Modernization?groupId=d63110a1-af9a-4b18-a770-bf272eaafe3b&tenantId=fb1f5cc5-be84-4881-b037-2d641aea97fd&ngc=true
A22: B-52 Legacy TS PWS | B22: https://serco.sharepoint.com/sites/B-52LegacyTSPWS | C22: https://serconagcch.sharepoint.us/sites/B-52LegacyTSPWS | D22: Brian.Townsend@serco-na.com | E22: Corporate Services | F22: Technology | G22: Wave 1B | H22: Migrate | I22: Sync Started
A23: B-52 Nuc Cert Collaboration | B23: https://serco.sharepoint.com/sites/B-52NucCertCollaboration | C23: https://serconagcch.sharepoint.us/sites/B-52NucCertCollaboration | D23: Brian.Townsend@serco-na.com | E23: Corporate Services | F23: Technology | G23: Wave 1B | H23: Migrate | I23: Sync Started | J23: https://gov.teams.microsoft.us/l/team/19%3Agcch%3Ac923882e1fae430db5a2a5b92ae4857e%40thread.tacv2/conversations?groupId=6558baf4-9ed8-4d91-95bf-6e8e7a9df34b&tenantId=fb1f5cc5-be84-4881-b037-2d641aea97fd
A24: B-52 TS | B24: https://serco.sharepoint.com/sites/B-52TS | C24: https://serconagcch.sharepoint.us/sites/B-52TS | D24: Gary.Leavy@serco-na.com | E24: Corporate Services | F24: Technology | G24: Wave 1B | H24: Migrate | I24: Sync Started
A25: CBP RFI | B25: https://serco.sharepoint.com/sites/CBPRFI | C25: https://serconagcch.sharepoint.us/sites/CBPRFI | D25: Maggie.Irons@serco-na.com | E25: Corporate Services | F25: Technology | G25: Wave 1B | H25: Migrate | I25: Sync Started
A26: Consultancy+ Army Market-Army Aviation Concept 2040-PACOM | B26: https://serco.sharepoint.com/sites/ConsultancyArmyMarket-ArmyAviationConcept2040-PACOM | D26: Michael.Bentley@serco-na.com | E26: Corporate Services | F26: Technology | G26: Wave 1B | H26: Migrate | I26: Migrated in Wave 1 - Agile Impact Army Team
A27: Agile Impact Army Team-Army Aviation Concept 2040-PACOM | B27: https://serco.sharepoint.com/sites/ConsultancyArmyMarket-ArmyAviationConcept2040-PACOM2 | D27: Michael.Bentley@serco-na.com | E27: Corporate Services | F27: Technology | G27: Wave 1B | H27: Migrate | I27: Migrated in Wave 1 - Agile Impact Army Team
A28: Agile Impact Army Team-FT Novosel UAS Industry Day and AVCOE Industry Day | B28: https://serco.sharepoint.com/sites/ConsultancyArmyMarket-FTNovoselUASIndustryDayandAVCOEIndustryDay | D28: Michael.Bentley@serco-na.com | E28: Corporate Services | F28: Technology | G28: Wave 1B | H28: Migrate | I28: Migrated in Wave 1 - Agile Impact Army Team
A29: DAF RCO 24-C-0007 | B29: https://serco.sharepoint.com/sites/DAFRCO24-C-0007 | C29: https://serconagcch.sharepoint.us/sites/DAFRCO24-C-0007 | D29: Alexander.Brown@serco-na.com | E29: Corporate Services | F29: Technology | G29: Wave 1B | H29: Migrate | I29: Migrated in Wave 1
A30: DAF RCO Bridge | B30: https://serco.sharepoint.com/sites/DAFRCOBridge | C30: https://serconagcch.sharepoint.us/sites/DAFRCOBridge | D30: Alexander.Brown@serco-na.com | E30: Corporate Services | F30: Technology | G30: Wave 1B | H30: Migrate | I30: Sync Started
A31: Defense Exportability Features - Bell | B31: https://serco.sharepoint.com/sites/DefenseExportabilityFeatures-Bell | C31: https://serconagcch.sharepoint.us/sites/DefenseExportabilityFeatures-Bell | D31: Joana.Rivera@serco-na.com | E31: Corporate Services | F31: Technology | G31: Wave 1B | H31: Migrate | I31: Sync Started
A32: DHS FPS Acquisition #32094 | B32: https://serco.sharepoint.com/sites/DHSFPSAcquisition32094 | C32: https://serconagcch.sharepoint.us/sites/DHSFPSAcquisition32094 | D32: Leonard.Geshan@serco-na.com | E32: Corporate Services | F32: Technology | G32: Wave 1B | H32: Migrate | I32: Sync Started
A33: Digital Enterprise BD Campaign-DE Consortium 2025 | B33: https://serco.sharepoint.com/sites/DigitalEnterprise-EWAACDEConsortium | D33: Robert.Hoffman@serco-na.com | E33: Corporate Services | F33: Technology | G33: Wave 1B | H33: Migrate | I33: Migrated in Wave 1 - Digital Enterprise BD Campaign
A34: DTIC IAC MAC - Pool One | B34: https://serco.sharepoint.com/sites/DTICIACMAC-PoolOne | C34: https://serconagcch.sharepoint.us/sites/DTICIACMAC-PoolOne | D34: Raymond.Wier@serco-na.com | E34: Corporate Services | F34: Technology | G34: Wave 1B | H34: Migrate | I34: Sync Started-connected
A35: DTIC IAC MAC - Pool One-IAC MAC 2673 448 SCMW | B35: https://serco.sharepoint.com/sites/DTICIACMAC-PoolOne-IACMAC2673448SCMW | C35: https://serconagcch.sharepoint.us/sites/DTICIACMAC-PoolOne | D35: Raymond.Wier@serco-na.com | E35: Corporate Services | F35: Technology | G35: Wave 1B | H35: Migrate | I35: Sync Started-connected
A36: DTIC IAC MAC - Pool One-MECSIP | B36: https://serco.sharepoint.com/sites/DTICIACMAC-PoolOne-MECSIP | C36: https://serconagcch.sharepoint.us/sites/DTICIACMAC-PoolOne | D36: Raymond.Wier@serco-na.com | E36: Corporate Services | F36: Technology | G36: Wave 1B | H36: Migrate | I36: Sync Started-connected
A37: DTIC TO # 1 Group | B37: https://serco.sharepoint.com/sites/DTICTO1Group | C37: https://serconagcch.sharepoint.us/sites/DTICTO1Group | D37: Robert.Hoffman@serco-na.com | E37: Corporate Services | F37: Technology | G37: Wave 1B | H37: Migrate | I37: Sync Started
A38: Eglin Wide Agile Acquisition Contract (EWAAC) | B38: https://serco.sharepoint.com/sites/EglinWideAgileAcquisitionContractEWAAC | C38: https://serconagcch.sharepoint.us/sites/EglinWideAgileAcquisitionContractEWAAC | D38: Robert.Hoffman@serco-na.com | E38: Corporate Services | F38: Technology | G38: Wave 1B | H38: Migrate | I38: Sync Started
A39: F-35 FM KBS | B39: https://serco.sharepoint.com/sites/F-35FMKBS | C39: https://serconagcch.sharepoint.us/sites/F-35FMKBS | D39: Alex.Stathopoulos@serco-na.com | E39: Corporate Services | F39: Technology | G39: Wave 1B | H39: Migrate | I39: Sync Started
A40: F-35 Logistics KBS | B40: https://serco.sharepoint.com/sites/F-35LogisticsKBS | C40: https://serconagcch.sharepoint.us/sites/F-35LogisticsKBS | D40: Alex.Stathopoulos@serco-na.com | E40: Corporate Services | F40: Technology | G40: Wave 1B | H40: Migrate | I40: Sync Started
...

Sheet Sheet2
A2: Nicholas.Abate@serco-na.com
A3: Nassebeh.StJohn@serco-na.com
A4: Timothy.Ablay@serco-na.com
A5: Jincy.Abraham@serco.ae
A6: Richard.Adleson@serco-na.com
A7: AdminM365AuditReport@serco.onmicrosoft.com
A8: AFSFMarketTeam@serco.onmicrosoft.com
A9: AFSFMarketTeam@serco.onmicrosoft.com
A10: Francisco.Aguilar@serco-na.com
A11: Kellie.Aguilera@serco-na.com
A12: rahern@serco-na.com
A13: Humdan.Ahmed@serco-na.com
... A1126: Raymond.Wier@serco-na.com

Sheet Permissions
A1: SiteUrl | B1: SiteTitle | C1: Source | D1: UserDisplay | E1: UserEmail | F1: Agile1B | G1: UserMapped | H1: ActiveUsers
A2: https://serco.sharepoint.com/sites/aaaa | B2: AAAA | C2: SiteUsers | D2: AAAA Members | E2: aaaa@serco.onmicrosoft.com | F2: Migrate | G2: =_xlfn.XLOOKUP(E2,[1]QuestALL!$B:$B,[1]QuestALL!$E:$E) -> #N/A | H2: =_xlfn.XLOOKUP(E2,'[2]exportUsers_2026-4-16'!$C:$C,'[2]exportUsers_2026-4-16'!$D:$D) -> #N/A
A3: https://serco.sharepoint.com/sites/aaaa | B3: AAAA | C3: SiteUsers | D3: AAAA Owners | E3: aaaa@serco.onmicrosoft.com | F3: Migrate | G3: =_xlfn.XLOOKUP(E3,[1]QuestALL!$B:$B,[1]QuestALL!$E:$E) -> #N/A | H3: =_xlfn.XLOOKUP(E3,'[2]exportUsers_2026-4-16'!$C:$C,'[2]exportUsers_2026-4-16'!$D:$D) -> #N/A
A4: https://serco.sharepoint.com/sites/aaaa | B4: AAAA | C4: SiteUsers | D4: AdminM365AuditReport | E4: AdminM365AuditReport@serco.onmicrosoft.com | F4: Migrate | G4: =_xlfn.XLOOKUP(E4,[1]QuestALL!$B:$B,[1]QuestALL!$E:$E) -> #N/A | H4: =_xlfn.XLOOKUP(E4,'[2]exportUsers_2026-4-16'!$C:$C,'[2]exportUsers_2026-4-16'!$D:$D) -> #N/A
A5: https://serco.sharepoint.com/sites/aaaa | B5: AAAA | C5: SiteUsers | D5: Bartholomew, Robert - Cloud Admin (Serco NA) | F5: Migrate | G5: =_xlfn.XLOOKUP(E5,[1]QuestALL!$B:$B,[1]QuestALL!$E:$E) -> 0 | H5: #N/A
A6: https://serco.sharepoint.com/sites/aaaa | B6: AAAA | C6: SiteUsers | D6: Everyone | F6: Migrate | G6: =_xlfn.XLOOKUP(E6,[1]QuestALL!$B:$B,[1]QuestALL!$E:$E) -> 0 | H6: #N/A
A7: https://serco.sharepoint.com/sites/aaaa | B7: AAAA | C7: SiteUsers | D7: Everyone except external users | F7: Migrate | G7: =_xlfn.XLOOKUP(E7,[1]QuestALL!$B:$B,[1]QuestALL!$E:$E) -> 0 | H7: #N/A
A8: https://serco.sharepoint.com/sites/aaaa | B8: AAAA | C8: SiteUsers | D8: Harris, Michael, J (Serco NA US) | E8: Michael.J.Harris@serco-na.com | F8: Migrate | G8: =_xlfn.XLOOKUP(E8,[1]QuestALL!$B:$B,[1]QuestALL!$E:$E) -> Migrated | H8: =_xlfn.XLOOKUP(E8,'[2]exportUsers_2026-4-16'!$C:$C,'[2]exportUsers_2026-4-16'!$D:$D) -> Member
A9: https://serco.sharepoint.com/sites/aaaa | B9: AAAA | C9: SiteUsers | D9: NT Service\spsearch | F9: Migrate | G9: =_xlfn.XLOOKUP(E9,[1]QuestALL!$B:$B,[1]QuestALL!$E:$E) -> 0 | H9: #N/A
A10: https://serco.sharepoint.com/sites/aaaa | B10: AAAA | C10: SiteUsers | D10: o-jtinsley | E10: o-jtinsley@serco.onmicrosoft.com | F10: Migrate | G10: =_xlfn.XLOOKUP(E10,[1]QuestALL!$B:$B,[1]QuestALL!$E:$E) -> #N/A | H10: =_xlfn.XLOOKUP(E10,'[2]exportUsers_2026-4-16'!$C:$C,'[2]exportUsers_2026-4-16'!$D:$D) -> #N/A
A11: https://serco.sharepoint.com/sites/aaaa | B11: AAAA | C11: SiteUsers | D11: o-jturner | E11: o-jturner@serco.onmicrosoft.com | F11: Migrate | G11: =_xlfn.XLOOKUP(E11,[1]QuestALL!$B:$B,[1]QuestALL!$E:$E) -> #N/A | H11: =_xlfn.XLOOKUP(E11,'[2]exportUsers_2026-4-16'!$C:$C,'[2]exportUsers_2026-4-16'!$D:$D) -> #N/A
A12: https://serco.sharepoint.com/sites/aaaa | B12: AAAA | C12: SiteUsers | D12: o-tlarese | E12: o-tlarese@serco.onmicrosoft.com | F12: Migrate | G12: =_xlfn.XLOOKUP(E12,[1]QuestALL!$B:$B,[1]QuestALL!$E:$E) -> #N/A | H12: =_xlfn.XLOOKUP(E12,'[2]exportUsers_2026-4-16'!$C:$C,'[2]exportUsers_2026-4-16'!$D:$D) -> #N/A
A13: https://serco.sharepoint.com/sites/aaaa | B13: AAAA | C13: SiteUsers | D13: SharePoint App | F13: Migrate | G13: =_xlfn.XLOOKUP(E13,[1]QuestALL!$B:$B,[1]QuestALL!$E:$E) -> 0 | H13: #N/A
A14: https://serco.sharepoint.com/sites/aaaa | B14: AAAA | C14: SiteUsers | D14: SR-SVC-SPO-Serco-CSL-Mig | E14: SR-SVC-SPO-Serco-CSL-Mig@serco.onmicrosoft.com | F14: Migrate | G14: =_xlfn.XLOOKUP(E14,[1]QuestALL!$B:$B,[1]QuestALL!$E:$E) -> #N/A | H14: =_xlfn.XLOOKUP(E14,'[2]exportUsers_2026-4-16'!$C:$C,'[2]exportUsers_2026-4-16'!$D:$D) -> #N/A
A15: https://serco.sharepoint.com/sites/aaaa | B15: AAAA | C15: SiteUsers | D15: System Account | F15: Migrate | G15: =_xlfn.XLOOKUP(E15,[1]QuestALL!$B:$B,[1]QuestALL!$E:$E) -> 0 | H15: #N/A
A16: https://serco.sharepoint.com/sites/aaaaplanning | B16: AAAAPlanning | C16: SiteUsers | D16: AAAAPlanning Members | E16: aaaaplanning@serco.onmicrosoft.com | F16: Migrate | G16: =_xlfn.XLOOKUP(E16,[1]QuestALL!$B:$B,[1]QuestALL!$E:$E) -> #N/A | H16: =_xlfn.XLOOKUP(E16,'[2]exportUsers_2026-4-16'!$C:$C,'[2]exportUsers_2026-4-16'!$D:$D) -> #N/A
A17: https://serco.sharepoint.com/sites/aaaaplanning | B17: AAAAPlanning | C17: SiteUsers | D17: AAAAPlanning Owners | E17: aaaaplanning@serco.onmicrosoft.com | F17: Migrate | G17: =_xlfn.XLOOKUP(E17,[1]QuestALL!$B:$B,[1]QuestALL!$E:$E) -> #N/A | H17: =_xlfn.XLOOKUP(E17,'[2]exportUsers_2026-4-16'!$C:$C,'[2]exportUsers_2026-4-16'!$D:$D) -> #N/A
A18: https://serco.sharepoint.com/sites/aaaaplanning | B18: AAAAPlanning | C18: SiteUsers | D18: AdminM365AuditReport | E18: AdminM365AuditReport@serco.onmicrosoft.com | F18: Migrate | G18: =_xlfn.XLOOKUP(E18,[1]QuestALL!$B:$B,[1]QuestALL!$E:$E) -> #N/A | H18: =_xlfn.XLOOKUP(E18,'[2]exportUsers_2026-4-16'!$C:$C,'[2]exportUsers_2026-4-16'!$D:$D) -> #N/A
A19: https://serco.sharepoint.com/sites/aaaaplanning | B19: AAAAPlanning | C19: SiteUsers | D19: Bartholomew, Robert - Cloud Admin (Serco NA) | F19: Migrate | G19: =_xlfn.XLOOKUP(E19,[1]QuestALL!$B:$B,[1]QuestALL!$E:$E) -> 0 | H19: #N/A
A20: https://serco.sharepoint.com/sites/aaaaplanning | B20: AAAAPlanning | C20: SiteUsers | D20: Everyone | F20: Migrate | G20: =_xlfn.XLOOKUP(E20,[1]QuestALL!$B:$B,[1]QuestALL!$E:$E) -> 0 | H20: #N/A
A21: https://serco.sharepoint.com/sites/aaaaplanning | B21: AAAAPlanning | C21: SiteUsers | D21: Everyone except external users | F21: Migrate | G21: =_xlfn.XLOOKUP(E21,[1]QuestALL!$B:$B,[1]QuestALL!$E:$E) -> 0 | H21: #N/A
A22: https://serco.sharepoint.com/sites/aaaaplanning | B22: AAAAPlanning | C22: SiteUsers | D22: NT Service\spsearch | F22: Migrate | G22: =_xlfn.XLOOKUP(E22,[1]QuestALL!$B:$B,[1]QuestALL!$E:$E) -> 0 | H22: #N/A
A23: https://serco.sharepoint.com/sites/aaaaplanning | B23: AAAAPlanning | C23: SiteUsers | D23: o-jtinsley | E23: o-jtinsley@serco.onmicrosoft.com | F23: Migrate | G23: =_xlfn.XLOOKUP(E23,[1]QuestALL!$B:$B,[1]QuestALL!$E:$E) -> #N/A | H23: =_xlfn.XLOOKUP(E23,'[2]exportUsers_2026-4-16'!$C:$C,'[2]exportUsers_2026-4-16'!$D:$D) -> #N/A
A24: https://serco.sharepoint.com/sites/aaaaplanning | B24: AAAAPlanning | C24: SiteUsers | D24: o-jturner | E24: o-jturner@serco.onmicrosoft.com | F24: Migrate | G24: =_xlfn.XLOOKUP(E24,[1]QuestALL!$B:$B,[1]QuestALL!$E:$E) -> #N/A | H24: =_xlfn.XLOOKUP(E24,'[2]exportUsers_2026-4-16'!$C:$C,'[2]exportUsers_2026-4-16'!$D:$D) -> #N/A
A25: https://serco.sharepoint.com/sites/aaaaplanning | B25: AAAAPlanning | C25: SiteUsers | D25: o-tlarese | E25: o-tlarese@serco.onmicrosoft.com | F25: Migrate | G25: =_xlfn.XLOOKUP(E25,[1]QuestALL!$B:$B,[1]QuestALL!$E:$E) -> #N/A | H25: =_xlfn.XLOOKUP(E25,'[2]exportUsers_2026-4-16'!$C:$C,'[2]exportUsers_2026-4-16'!$D:$D) -> #N/A
A26: https://serco.sharepoint.com/sites/aaaaplanning | B26: AAAAPlanning | C26: SiteUsers | D26: SharePoint App | F26: Migrate | G26: =_xlfn.XLOOKUP(E26,[1]QuestALL!$B:$B,[1]QuestALL!$E:$E) -> 0 | H26: #N/A
A27: https://serco.sharepoint.com/sites/aaaaplanning | B27: AAAAPlanning | C27: SiteUsers | D27: SR-SVC-SPO-Serco-CSL-Mig | E27: SR-SVC-SPO-Serco-CSL-Mig@serco.onmicrosoft.com | F27: Migrate | G27: =_xlfn.XLOOKUP(E27,[1]QuestALL!$B:$B,[1]QuestALL!$E:$E) -> #N/A | H27: =_xlfn.XLOOKUP(E27,'[2]exportUsers_2026-4-16'!$C:$C,'[2]exportUsers_2026-4-16'!$D:$D) -> #N/A
A28: https://serco.sharepoint.com/sites/aaaaplanning | B28: AAAAPlanning | C28: SiteUsers | D28: System Account | F28: Migrate | G28: =_xlfn.XLOOKUP(E28,[1]QuestALL!$B:$B,[1]QuestALL!$E:$E) -> 0 | H28: #N/A
A29: https://serco.sharepoint.com/sites/AFSFMarketTeam | B29: Acquisition Management (AQM) | C29: SiteUsers | D29: Abate, Nicholas (Serco NA) | E29: Nicholas.Abate@serco-na.com | F29: Migrate | G29: =_xlfn.XLOOKUP(E29,[1]QuestALL!$B:$B,[1]QuestALL!$E:$E) -> #N/A | H29: =_xlfn.XLOOKUP(E29,'[2]exportUsers_2026-4-16'!$C:$C,'[2]exportUsers_2026-4-16'!$D:$D) -> #N/A
A30: https://serco.sharepoint.com/sites/AFSFMarketTeam | B30: Acquisition Management (AQM) | C30: SiteUsers | D30: Abdeljaber, Jennifer, J (Serco NA) | E30: Nassebeh.StJohn@serco-na.com | F30: Migrate | G30: =_xlfn.XLOOKUP(E30,[1]QuestALL!$B:$B,[1]QuestALL!$E:$E) -> #N/A | H30: =_xlfn.XLOOKUP(E30,'[2]exportUsers_2026-4-16'!$C:$C,'[2]exportUsers_2026-4-16'!$D:$D) -> #N/A
A31: https://serco.sharepoint.com/sites/AFSFMarketTeam | B31: Acquisition Management (AQM) | C31: SiteUsers | D31: Ablay, Timothy (Serco NA US) | E31: Timothy.Ablay@serco-na.com | F31: Migrate | G31: =_xlfn.XLOOKUP(E31,[1]QuestALL!$B:$B,[1]QuestALL!$E:$E) -> Migrated | H31: =_xlfn.XLOOKUP(E31,'[2]exportUsers_2026-4-16'!$C:$C,'[2]exportUsers_2026-4-16'!$D:$D) -> Member
A32: https://serco.sharepoint.com/sites/AFSFMarketTeam | B32: Acquisition Management (AQM) | C32: SiteUsers | D32: Abraham, Jincy (Serco ME) | E32: Jincy.Abraham@serco.ae | F32: Migrate | G32: =_xlfn.XLOOKUP(E32,[1]QuestALL!$B:$B,[1]QuestALL!$E:$E) -> #N/A | H32: =_xlfn.XLOOKUP(E32,'[2]exportUsers_2026-4-16'!$C:$C,'[2]exportUsers_2026-4-16'!$D:$D) -> #N/A
A33: https://serco.sharepoint.com/sites/AFSFMarketTeam | B33: Acquisition Management (AQM) | C33: SiteUsers | D33: Adleson, Richard, B (Serco NA US) | E33: Richard.Adleson@serco-na.com | F33: Migrate | G33: =_xlfn.XLOOKUP(E33,[1]QuestALL!$B:$B,[1]QuestALL!$E:$E) -> #N/A | H33: =_xlfn.XLOOKUP(E33,'[2]exportUsers_2026-4-16'!$C:$C,'[2]exportUsers_2026-4-16'!$D:$D) -> #N/A
A34: https://serco.sharepoint.com/sites/AFSFMarketTeam | B34: Acquisition Management (AQM) | C34: SiteUsers | D34: AdminM365AuditReport | E34: AdminM365AuditReport@serco.onmicrosoft.com | F34: Migrate | G34: =_xlfn.XLOOKUP(E34,[1]QuestALL!$B:$B,[1]QuestALL!$E:$E) -> #N/A | H34: =_xlfn.XLOOKUP(E34,'[2]exportUsers_2026-4-16'!$C:$C,'[2]exportUsers_2026-4-16'!$D:$D) -> #N/A
A35: https://serco.sharepoint.com/sites/AFSFMarketTeam | B35: Acquisition Management (AQM) | C35: SiteUsers | D35: AF/SF Market Team Members | E35: AFSFMarketTeam@serco.onmicrosoft.com | F35: Migrate | G35: =_xlfn.XLOOKUP(E35,[1]QuestALL!$B:$B,[1]QuestALL!$E:$E) -> #N/A | H35: =_xlfn.XLOOKUP(E35,'[2]exportUsers_2026-4-16'!$C:$C,'[2]exportUsers_2026-4-16'!$D:$D) -> #N/A
A36: https://serco.sharepoint.com/sites/AFSFMarketTeam | B36: Acquisition Management (AQM) | C36: SiteUsers | D36: AF/SF Market Team Owners | E36: AFSFMarketTeam@serco.onmicrosoft.com | F36: Migrate | G36: =_xlfn.XLOOKUP(E36,[1]QuestALL!$B:$B,[1]QuestALL!$E:$E) -> #N/A | H36: =_xlfn.XLOOKUP(E36,'[2]exportUsers_2026-4-16'!$C:$C,'[2]exportUsers_2026-4-16'!$D:$D) -> #N/A
A37: https://serco.sharepoint.com/sites/AFSFMarketTeam | B37: Acquisition Management (AQM) | C37: SiteUsers | D37: Aguilar, Francisco (Serco NA US) | E37: Francisco.Aguilar@serco-na.com | F37: Migrate | G37: =_xlfn.XLOOKUP(E37,[1]QuestALL!$B:$B,[1]QuestALL!$E:$E) -> #N/A | H37: =_xlfn.XLOOKUP(E37,'[2]exportUsers_2026-4-16'!$C:$C,'[2]exportUsers_2026-4-16'!$D:$D) -> Member
A38: https://serco.sharepoint.com/sites/AFSFMarketTeam | B38: Acquisition Management (AQM) | C38: SiteUsers | D38: Aguilera, Kellie (Serco NA US) | E38: Kellie.Aguilera@serco-na.com | F38: Migrate | G38: =_xlfn.XLOOKUP(E38,[1]QuestALL!$B:$B,[1]QuestALL!$E:$E) -> #N/A | H38: =_xlfn.XLOOKUP(E38,'[2]exportUsers_2026-4-16'!$C:$C,'[2]exportUsers_2026-4-16'!$D:$D) -> #N/A
A39: https://serco.sharepoint.com/sites/AFSFMarketTeam | B39: Acquisition Management (AQM) | C39: SiteUsers | D39: Ahern, Robert, E (Serco NA US) | E39: rahern@serco-na.com | F39: Migrate | G39: =_xlfn.XLOOKUP(E39,[1]QuestALL!$B:$B,[1]QuestALL!$E:$E) -> Mapped | H39: =_xlfn.XLOOKUP(E39,'[2]exportUsers_2026-4-16'!$C:$C,'[2]exportUsers_2026-4-16'!$D:$D) -> Member
A40: https://serco.sharepoint.com/sites/AFSFMarketTeam | B40: Acquisition Management (AQM) | C40: SiteUsers | D40: Ahmed, Humdan, J (Serco NA US) | E40: Humdan.Ahmed@serco-na.com | F40: Migrate | G40: =_xlfn.XLOOKUP(E40,[1]QuestALL!$B:$B,[1]QuestALL!$E:$E) -> Mapped | H40: =_xlfn.XLOOKUP(E40,'[2]exportUsers_2026-4-16'!$C:$C,'[2]exportUsers_2026-4-16'!$D:$D) -> Member
...

Sheet AFSFMarketTeam
A1: https://serco.sharepoint.com/sites/AFSFMarketTeam
A2: Francisco.Aguilar@serco-na.com | B2: =_xlfn.XLOOKUP(A2,'[3]SAM ACCT LIST'!$B:$B,'[3]SAM ACCT LIST'!$F:$F) -> Francisco.Aguilar@serco-na.us | C2: =_xlfn.XLOOKUP(A2,Permissions!E:E,Permissions!D:D) -> Aguilar, Francisco (Serco NA US)
A3: Tanvir.Ahmed@serco-na.com | B3: =_xlfn.XLOOKUP(A3,'[3]SAM ACCT LIST'!$B:$B,'[3]SAM ACCT LIST'!$F:$F) -> Tanvir.Ahmed@serco-na.us | C3: =_xlfn.XLOOKUP(A3,Permissions!E:E,Permissions!D:D) -> Ahmed, Tanvir, N (Serco NA)
A4: Lucille.Arguijo@serco-na.com | B4: =_xlfn.XLOOKUP(A4,'[3]SAM ACCT LIST'!$B:$B,'[3]SAM ACCT LIST'!$F:$F) -> Lucille.Arguijo@serco-na.us | C4: =_xlfn.XLOOKUP(A4,Permissions!E:E,Permissions!D:D) -> Arguijo, Lucille (Serco NA US)
A5: Sarah.Arthurs@serco-na.com | B5: =_xlfn.XLOOKUP(A5,'[3]SAM ACCT LIST'!$B:$B,'[3]SAM ACCT LIST'!$F:$F) -> Sarah.Arthurs@serco-na.us | C5: =_xlfn.XLOOKUP(A5,Permissions!E:E,Permissions!D:D) -> Arthurs, Sarah (Serco NA)
A6: Ishmael.Asah@serco-na.com | B6: =_xlfn.XLOOKUP(A6,'[3]SAM ACCT LIST'!$B:$B,'[3]SAM ACCT LIST'!$F:$F) -> Ishmael.Asah@serco-na.us | C6: =_xlfn.XLOOKUP(A6,Permissions!E:E,Permissions!D:D) -> Asah, Ishmael (Serco NA US)
A7: Zoya.Augustus@serco-na.com | B7: =_xlfn.XLOOKUP(A7,'[3]SAM ACCT LIST'!$B:$B,'[3]SAM ACCT LIST'!$F:$F) -> Zoya.Augustus@serco-na.us | C7: =_xlfn.XLOOKUP(A7,Permissions!E:E,Permissions!D:D) -> Augustus, Zoya (Serco NA US)
A8: Mel.Austin@serco-na.com | B8: =_xlfn.XLOOKUP(A8,'[3]SAM ACCT LIST'!$B:$B,'[3]SAM ACCT LIST'!$F:$F) -> Mel.Austin@serco-na.us | C8: =_xlfn.XLOOKUP(A8,Permissions!E:E,Permissions!D:D) -> Austin, Mel, C (Serco NA US)
A9: Danielle.Bartley@serco-na.com | B9: =_xlfn.XLOOKUP(A9,'[3]SAM ACCT LIST'!$B:$B,'[3]SAM ACCT LIST'!$F:$F) -> Danielle.Bartley@serco-na.us | C9: =_xlfn.XLOOKUP(A9,Permissions!E:E,Permissions!D:D) -> Bartley, Danielle (Serco NA)
A10: Alejandro.Batista@serco-na.com | B10: =_xlfn.XLOOKUP(A10,'[3]SAM ACCT LIST'!$B:$B,'[3]SAM ACCT LIST'!$F:$F) -> Alejandro.Batista@serco-na.us | C10: =_xlfn.XLOOKUP(A10,Permissions!E:E,Permissions!D:D) -> Batista, Alejandro (Serco NA US)
A11: Sabrina.Baumler@serco-na.com | B11: =_xlfn.XLOOKUP(A11,'[3]SAM ACCT LIST'!$B:$B,'[3]SAM ACCT LIST'!$F:$F) -> Sabrina.Baumler@serco-na.us | C11: =_xlfn.XLOOKUP(A11,Permissions!E:E,Permissions!D:D) -> Baumler, Sabrina, E (Serco NA US)
A12: Amber.Bell@serco-na.com | B12: =_xlfn.XLOOKUP(A12,'[3]SAM ACCT LIST'!$B:$B,'[3]SAM ACCT LIST'!$F:$F) -> Amber.Bell@serco-na.us | C12: =_xlfn.XLOOKUP(A12,Permissions!E:E,Permissions!D:D) -> Bell, Amber, D (Serco NA)
A13: Edwin.Bell@serco-na.com | B13: =_xlfn.XLOOKUP(A13,'[3]SAM ACCT LIST'!$B:$B,'[3]SAM ACCT LIST'!$F:$F) -> Edwin.Bell@serco-na.us | C13: =_xlfn.XLOOKUP(A13,Permissions!E:E,Permissions!D:D) -> Bell, Edwin, M (Serco NA)
... A146: Kameron.Zepeda@serco-na.com | B146: =_xlfn.XLOOKUP(A146,'[3]SAM ACCT LIST'!$B:$B,'[3]SAM ACCT LIST'!$F:$F) -> Kameron.Zepeda@serco-na.us | C146: =_xlfn.XLOOKUP(A146,Permissions!E:E,Permissions!D:D) -> Zepeda, Kam, N (Serco NA US)

Sheet WBB
A1: UserEmail | B1: WBB
A2: Francisco.Aguilar@serco-na.com | B2: =_xlfn.XLOOKUP(A2,AFSFMarketTeam!A:A,AFSFMarketTeam!B:B) -> Francisco.Aguilar@serco-na.us
A3: Laeeqa.Ahmad@serco-na.com | B3: =_xlfn.XLOOKUP(A3,AFSFMarketTeam!A:A,AFSFMarketTeam!B:B) -> #N/A
A4: Eric.Anderson@serco-na.com | B4: =_xlfn.XLOOKUP(A4,AFSFMarketTeam!A:A,AFSFMarketTeam!B:B) -> #N/A
A5: Anthony.Androsky@serco-na.com | B5: =_xlfn.XLOOKUP(A5,AFSFMarketTeam!A:A,AFSFMarketTeam!B:B) -> #N/A
A6: John.Arriza@serco-na.com | B6: =_xlfn.XLOOKUP(A6,AFSFMarketTeam!A:A,AFSFMarketTeam!B:B) -> #N/A
A7: Justice.Bailey@serco-na.com | B7: =_xlfn.XLOOKUP(A7,AFSFMarketTeam!A:A,AFSFMarketTeam!B:B) -> #N/A
A8: Phillip.Baker@serco-na.com | B8: =_xlfn.XLOOKUP(A8,AFSFMarketTeam!A:A,AFSFMarketTeam!B:B) -> #N/A
A9: Velincia.Baker@serco-na.com | B9: =_xlfn.XLOOKUP(A9,AFSFMarketTeam!A:A,AFSFMarketTeam!B:B) -> #N/A
A10: Sarah.Ballard@serco-na.com | B10: =_xlfn.XLOOKUP(A10,AFSFMarketTeam!A:A,AFSFMarketTeam!B:B) -> #N/A
A11: Veronica.Banton@serco-na.com | B11: =_xlfn.XLOOKUP(A11,AFSFMarketTeam!A:A,AFSFMarketTeam!B:B) -> #N/A
A12: Robert.Barber@serco-na.com | B12: =_xlfn.XLOOKUP(A12,AFSFMarketTeam!A:A,AFSFMarketTeam!B:B) -> #N/A
A13: Amber.Bell@serco-na.com | B13: =_xlfn.XLOOKUP(A13,AFSFMarketTeam!A:A,AFSFMarketTeam!B:B) -> Amber.Bell@serco-na.us
... A188: Casey.Zerkle@serco-na.com | B188: =_xlfn.XLOOKUP(A188,AFSFMarketTeam!A:A,AFSFMarketTeam!B:B) -> #N/A

Sheet UserAnalysis
A1: ActiveUsers | B1: Member
A3: Row Labels | B3: Count of SiteUrl
A4: Aaron.Runion@serco-na.com | B4: 1
A5: Aaron.Webb@serco-na.com | B5: 1
A6: Abroadger.Lipardo@serco-na.com | B6: 1
A7: Achim.Prosser@serco-na.com | B7: 1
A8: Adam.Blankenship@serco-na.com | B8: 14
A9: Adam.Heathman@serco-na.com | B9: 1
A10: Adam.Rosnick@serco-na.com | B10: 1
A11: Adam.Taylor@serco-na.com | B11: 1
A12: Adrienne.Kempton@serco-na.com | B12: 1
A13: ahunter@serco-na.com | B13: 3
A14: Alan.Cruz@serco-na.com | B14: 4
A15: Alan.Lipzin@serco-na.com | B15: 1
... A1014: Grand Total | B1014: 2213

Sheet SiteAnalysis
A1: UserMapped | B1: #N/A
B3: Column Labels
B4: Member | D4: #N/A | F4: Total Count of ActiveUsers | G4: Total Count of UserEmail
A5: Row Labels | B5: Count of ActiveUsers | C5: Count of UserEmail | D5: Count of ActiveUsers | E5: Count of UserEmail
A6: https://serco.sharepoint.com/sites/aaaa | D6: 13 | E6: 7 | F6: 13 | G6: 7
A7: https://serco.sharepoint.com/sites/aaaaplanning | D7: 12 | E7: 7 | F7: 12 | G7: 7
A8: https://serco.sharepoint.com/sites/AFSFMarketTeam | B8: 150 | C8: 150 | D8: 547 | E8: 540 | F8: 697 | G8: 690
A9: https://serco.sharepoint.com/sites/AFSFMarketTeam-AUiXBriefing | D9: 7 | E9: 1 | F9: 7 | G9: 1
A10: https://serco.sharepoint.com/sites/AFSFMarketTeam-RS3PMPNTPSSVP31231 | D10: 7 | E10: 1 | F10: 7 | G10: 1
A11: https://serco.sharepoint.com/sites/AFSFMarketTeam-Training | D11: 7 | E11: 1 | F11: 7 | G11: 1
A12: https://serco.sharepoint.com/sites/AFSFMarketTeam-USSFTraining | D12: 8 | E12: 2 | F12: 8 | G12: 2
A13: https://serco.sharepoint.com/sites/AFWROSpecialProjects | B13: 1 | C13: 1 | D13: 36 | E13: 28 | F13: 37 | G13: 29
A14: https://serco.sharepoint.com/sites/AFWROSpecialProjects-HBGSpecialProjects2 | D14: 14 | E14: 8 | F14: 14 | G14: 8
A15: https://serco.sharepoint.com/sites/AFWROSpecialProjects-programatics | D15: 9 | E15: 3 | F15: 9 | G15: 3
A16: https://serco.sharepoint.com/sites/ahfrm | D16: 15 | E16: 9 | F16: 15 | G16: 9
A17: https://serco.sharepoint.com/sites/AHFRMDTICKICKOFF-AHFRMDTICManagementChannel | D17: 20 | E17: 14 | F17: 20 | G17: 14
A18: https://serco.sharepoint.com/sites/AHFRMManufacturingEmails | D18: 11 | E18: 5 | F18: 11 | G18: 5
A19: https://serco.sharepoint.com/sites/AmeriCorpsWorkforceAnalysis | D19: 21 | E19: 15 | F19: 21 | G19: 15
A20: https://serco.sharepoint.com/sites/AngeloFiles | D20: 13 | E20: 7 | F20: 13 | G20: 7
A21: https://serco.sharepoint.com/sites/ArmedOverwatch | D21: 23 | E21: 17 | F21: 23 | G21: 17
A22: https://serco.sharepoint.com/sites/ArmyCONOPSTeam | B22: 1 | C22: 1 | D22: 67 | E22: 60 | F22: 68 | G22: 61
A23: https://serco.sharepoint.com/sites/armyteam | D23: 15 | E23: 9 | F23: 15 | G23: 9
A24: https://serco.sharepoint.com/sites/AUSAGroup | B24: 1 | C24: 1 | D24: 34 | E24: 27 | F24: 35 | G24: 28
A25: https://serco.sharepoint.com/sites/B-52DTICIACTeam | D25: 31 | E25: 24 | F25: 31 | G25: 24
A26: https://serco.sharepoint.com/sites/B-52LegacyTSPWS | D26: 17 | E26: 11 | F26: 17 | G26: 11
A27: https://serco.sharepoint.com/sites/B-52NucCertCollaboration | D27: 20 | E27: 14 | F27: 20 | G27: 14
A28: https://serco.sharepoint.com/sites/B-52TS | D28: 19 | E28: 13 | F28: 19 | G28: 13
A29: https://serco.sharepoint.com/sites/CBPRFI | D29: 9 | E29: 3 | F29: 9 | G29: 3
A30: https://serco.sharepoint.com/sites/ConsultancyArmyMarket-ArmyAviationConcept2040-PACOM | D30: 7 | E30: 1 | F30: 7 | G30: 1
A31: https://serco.sharepoint.com/sites/ConsultancyArmyMarket-ArmyAviationConcept2040-PACOM2 | D31: 9 | E31: 3 | F31: 9 | G31: 3
A32: https://serco.sharepoint.com/sites/ConsultancyArmyMarket-FTNovoselUASIndustryDayandAVCOEIndustryDay | D32: 9 | E32: 3 | F32: 9 | G32: 3
A33: https://serco.sharepoint.com/sites/DAFRCO24-C-0007 | D33: 17 | E33: 11 | F33: 17 | G33: 11
A34: https://serco.sharepoint.com/sites/DAFRCOBridge | D34: 11 | E34: 4 | F34: 11 | G34: 4
A35: https://serco.sharepoint.com/sites/DefenseExportabilityFeatures-Bell | D35: 17 | E35: 11 | F35: 17 | G35: 11
A36: https://serco.sharepoint.com/sites/DHSFPSAcquisition32094 | D36: 15 | E36: 9 | F36: 15 | G36: 9
A37: https://serco.sharepoint.com/sites/DigitalEnterprise-EWAACDEConsortium | D37: 12 | E37: 5 | F37: 12 | G37: 5
A38: https://serco.sharepoint.com/sites/DTICIACMAC-PoolOne | B38: 2 | C38: 2 | D38: 12 | E38: 6 | F38: 14 | G38: 8
A39: https://serco.sharepoint.com/sites/DTICIACMAC-PoolOne-IACMAC2673448SCMW | D39: 8 | E39: 2 | F39: 8 | G39: 2
A40: https://serco.sharepoint.com/sites/DTICIACMAC-PoolOne-MECSIP | D40: 8 | E40: 2 | F40: 8 | G40: 2
A41: https://serco.sharepoint.com/sites/DTICTO1Group | D41: 13 | E41: 7 | F41: 13 | G41: 7
...

Sheet AdditionalUsers
A1: UserEmail
A2: Francisco.Aguilar@serco-na.com
A3: Tanvir.Ahmed@serco-na.com
A4: Richard.Antorietto@serco-na.com
A5: Lucille.Arguijo@serco-na.com
A6: Sarah.Arthurs@serco-na.com
A7: Ishmael.Asah@serco-na.com
A8: Zoya.Augustus@serco-na.com
A9: Mel.Austin@serco-na.com
A10: Danielle.Bartley@serco-na.com
A11: Alejandro.Batista@serco-na.com
A12: Sabrina.Baumler@serco-na.com
... A350: Ronald.Rodriguez@serco-na.com

Sheet AdditionalUsersMinusBigSites
A1: Commercial UPN | B1: GCCH UPN | C1: Notes
A2: Levern.Keels@serco-na.com | B2: Levern.Keels@serco-na.us
A3: Ken.Long@serco-na.com | B3: Ken.Long@serco-na.us
A4: Dianna.Savage@serco-na.com | B4: Dianna.Savage@serco-na.us | C4: no longer exists
A5: Paulette.Terrell@serco-na.com | B5: Paulette.Terrell@serco-na.us
A6: Andy.AguilarSiguenza@serco-na.com | B6: Andy.AguilarSiguenza@serco-na.us
A7: David.Masini@serco-na.com | B7: David.Masini@serco-na.us
A8: Maura.Connolly@serco-na.com | B8: Maura.Connolly@serco-na.us
A9: Bryan.Miller@serco-na.com | B9: Bryan.Miller@serco-na.us
A10: Gabriel.Gentry@serco-na.com | B10: Gabriel.Gentry@serco-na.us
A11: Yolande.Parahoo-Doug@serco-na.com | B11: Yolande.Parahoo-Doug@serco-na.us
A12: Regina.Seetoo@serco-na.com | B12: Regina.Seetoo@serco-na.us
A13: Lorenzo.White@serco-na.com | B13: Lorenzo.White@serco-na.us | C13: moved in wave 1
A14: Ronald.Rodriguez@serco-na.com | B14: Ronald.Rodriguez@serco-na.us
